Workbook

Sheet Processor Cost - Schedule
A1: Summary
C2: Category | D2: Total | F2: 1 | G2: 2 | H2: 3 | I2: 4 | J2: 5 | K2: 6 | L2: 7 | M2: 8 | N2: 9 | O2: 10 | P2: 11 | Q2: 12
C3: =A12 -> Equipment & Materials | D3: =SUM(F3:Q3) -> 5438875 | F3: =F50 -> 3228958.3 | G3: =G50 -> 1227958.3 | H3: =H50 -> 981958.33 | I3: =I50 -> 0 | J3: =J50 -> 0 | K3: =K50 -> 0 | L3: =L50 -> 0 | M3: =M50 -> 0 | ... Q3: =Q50 -> 0
C4: =A52 -> Facilities & Auxillary Support Systems | D4: =SUM(F4:Q4) -> 3674050 | F4: =F73 -> 1309683.3 | G4: =G73 -> 994683.33 | H4: =H73 -> 994683.33 | I4: =I73 -> 375000 | J4: =J73 -> 0 | K4: =K73 -> 0 | L4: =L73 -> 0 | M4: =M73 -> 0 | ... Q4: =Q73 -> 0
C5: =A75 -> Operating Costs | D5: =SUM(F5:Q5) -> 720500 | F5: =F104 -> 91450 | G5: =G104 -> 27950 | H5: =H104 -> 27950 | I5: =I104 -> 27950 | J5: =J104 -> 27950 | K5: =K104 -> 204016.67 | L5: =L104 -> 144616.67 | M5: =M104 -> 144616.67 | ... Q5: =Q104 -> 6000
C6: =A106 -> Professional Services | D6: =SUM(F6:Q6) -> 401400 | F6: =F118 -> 364550 | G6: =G118 -> 4550 | H6: =H118 -> 4550 | I6: =I118 -> 4550 | J6: =J118 -> 9550 | K6: =K118 -> 4550 | L6: =L118 -> 4550 | M6: =M118 -> 4550 | ... Q6: =Q118 -> 0
C7: =A120 -> Workforce - Role - Pay Rate | D7: =SUM(F7:Q7) -> 2775367.6 | F7: =F150 -> 338436.18 | G7: =G150 -> 338436.18 | H7: =H150 -> 338436.18 | I7: =I150 -> 338436.18 | J7: =J150 -> 355405.72 | K7: =K150 -> 355405.72 | L7: =L150 -> 355405.72 | M7: =M150 -> 355405.72 | ... Q7: =Q150 -> 0
C9: Total Cost Build 1 SENS Processor | D9: =SUM(D3:D7) -> 13010193 | F9: =SUM(F3:F7) -> 5333077.9 | G9: =SUM(G3:G7) -> 2593577.9 | H9: =SUM(H3:H7) -> 2347577.9 | I9: =SUM(I3:I7) -> 745936.18 | J9: =SUM(J3:J7) -> 392905.72 | K9: =SUM(K3:K7) -> 563972.39 | L9: =SUM(L3:L7) -> 504572.39 | M9: =SUM(M3:M7) -> 504572.39 | ... Q9: =SUM(Q3:Q7) -> 6000
A12: Equipment & Materials
B13: Category | C13: Item | D13: Per Unit (Imported) | E13: Disc Rate | F13: 1 | G13: 2 | H13: 3 | I13: 4 | J13: 5 | K13: 6 | L13: 7 | M13: 8 | N13: 9 | O13: 10 | P13: 11 | Q13: 12
B14: Equipment & Materials
C15: Pack column, demister, liquid ring | D15: ='IMPORT_OK Model'!E136/8 -> 233125 | E15: 0.2 | F15: =$D15*(1-$E15)/3 -> 62166.667 | G15: =$D15*(1-$E15)/3 -> 62166.667 | H15: =$D15*(1-$E15)/3 -> 62166.667 | I15: 0 | J15: 0 | K15: 0 | L15: 0 | M15: 0 | N15: 0 | O15: 0 | P15: 0 | Q15: 0
C16: Ovens | D16: ='IMPORT_OK Model'!E137/8 -> 609375 | E16: 0.2 | F16: =$D16*(1-$E16)/3 -> 162500 | G16: =$D16*(1-$E16)/3 -> 162500 | H16: =$D16*(1-$E16)/3 -> 162500 | I16: 0 | J16: 0 | K16: 0 | L16: 0 | M16: 0 | N16: 0 | O16: 0 | P16: 0 | Q16: 0
C17: Pipe, fittings, auger tube shafts | D17: ='IMPORT_OK Model'!E138/8 -> 516250 | E17: 0.2 | F17: =$D17*(1-$E17)/3 -> 137666.67 | G17: =$D17*(1-$E17)/3 -> 137666.67 | H17: =$D17*(1-$E17)/3 -> 137666.67 | I17: 0 | J17: 0 | K17: 0 | L17: 0 | M17: 0 | N17: 0 | O17: 0 | P17: 0 | Q17: 0
C18: Weight hopper feed system | D18: ='IMPORT_OK Model'!E139/8 -> 582500 | E18: 0.2 | F18: =$D18*(1-$E18)/3 -> 155333.33 | G18: =$D18*(1-$E18)/3 -> 155333.33 | H18: =$D18*(1-$E18)/3 -> 155333.33 | I18: 0 | J18: 0 | K18: 0 | L18: 0 | M18: 0 | N18: 0 | O18: 0 | P18: 0 | Q18: 0
B19: National Tube sales
C20: Auger tubes | D20: ='IMPORT_OK Model'!E141/8 -> 330000 | E20: 0.2 | F20: =$D20*(1-$E20)/2 -> 132000 | G20: =$D20*(1-$E20)/2 -> 132000 | H20: 0 | I20: 0 | J20: 0 | K20: 0 | L20: 0 | M20: 0 | N20: 0 | O20: 0 | P20: 0 | Q20: 0
B21: Thomas Conveyor
C22: Auger flights | D22: ='IMPORT_OK Model'!E143/8 -> 160000 | E22: 0.2 | F22: =$D22*(1-$E22)/2 -> 64000 | G22: =$D22*(1-$E22)/2 -> 64000 | H22: 0 | I22: 0 | J22: 0 | K22: 0 | L22: 0 | M22: 0 | N22: 0 | O22: 0 | P22: 0 | Q22: 0
C23: Tapered Screw for weigh hopper | D23: ='IMPORT_OK Model'!E144/8 -> 125000 | E23: 0.2 | F23: =$D23*(1-$E23)/2 -> 50000 | G23: =$D23*(1-$E23)/2 -> 50000 | H23: 0 | I23: 0 | J23: 0 | K23: 0 | L23: 0 | M23: 0 | N23: 0 | O23: 0 | P23: 0 | Q23: 0
B24: Controls, motors and pumps
C25: Control Automation Component | D25: ='IMPORT_OK Model'!E146/8 -> 478125 | E25: 0.2 | F25: =$D25*(1-$E25) -> 382500 | G25: 0 | H25: 0 | I25: 0 | J25: 0 | K25: 0 | L25: 0 | M25: 0 | N25: 0 | O25: 0 | P25: 0 | Q25: 0
C26: Motors, gearboxes, drives, bucket elevators | D26: ='IMPORT_OK Model'!E147/8 -> 356250 | E26: 0.2 | F26: =$D26*(1-$E26) -> 285000 | G26: 0 | H26: 0 | I26: 0 | J26: 0 | K26: 0 | L26: 0 | M26: 0 | N26: 0 | O26: 0 | P26: 0 | Q26: 0
C27: Chiller Contols & Electrical | D27: ='IMPORT_OK Model'!E148/8 -> 197500 | E27: 0.2 | F27: =$D27*(1-$E27) -> 158000 | G27: 0 | H27: 0 | I27: 0 | J27: 0 | K27: 0 | L27: 0 | M27: 0 | N27: 0 | O27: 0 | P27: 0 | Q27: 0
C28: Myers (Flapper valves) | D28: ='IMPORT_OK Model'!E149/8 -> 112500 | E28: 0.2 | F28: =$D28*(1-$E28) -> 90000 | G28: 0 | H28: 0 | I28: 0 | J28: 0 | K28: 0 | L28: 0 | M28: 0 | N28: 0 | O28: 0 | P28: 0 | Q28: 0
C29: Myers Aubrey (Steam, and Gas Processing control valves) | D29: ='IMPORT_OK Model'!E150/8 -> 335625 | E29: 0.2 | F29: =$D29*(1-$E29) -> 268500 | G29: 0 | H29: 0 | I29: 0 | J29: 0 | K29: 0 | L29: 0 | M29: 0 | N29: 0 | O29: 0 | P29: 0 | Q29: 0
C30: Myers Aubrey (Flow meters) | D30: ='IMPORT_OK Model'!E151/8 -> 170000 | E30: 0.2 | F30: =$D30*(1-$E30) -> 136000 | G30: 0 | H30: 0 | I30: 0 | J30: 0 | K30: 0 | L30: 0 | M30: 0 | N30: 0 | O30: 0 | P30: 0 | Q30: 0
C31: Automatic Pump (Vacuum and Oil Water Separator) | D31: ='IMPORT_OK Model'!E152/8 -> 172500 | E31: 0.2 | F31: =$D31*(1-$E31) -> 138000 | G31: 0 | H31: 0 | I31: 0 | J31: 0 | K31: 0 | L31: 0 | M31: 0 | N31: 0 | O31: 0 | P31: 0 | Q31: 0
C32: Roberts & Spencer (Pressure transmitters, Vac Control Valves, level indicators) | D32: ='IMPORT_OK Model'!E153/8 -> 168125 | E32: 0.2 | F32: =$D32*(1-$E32) -> 134500 | G32: 0 | H32: 0 | I32: 0 | J32: 0 | K32: 0 | L32: 0 | M32: 0 | N32: 0 | O32: 0 | P32: 0 | Q32: 0
C33: Switch Gear and Generator | D33: ='IMPORT_OK Model'!E154/8 -> 203125 | E33: 0.2 | F33: =$D33*(1-$E33) -> 162500 | G33: 0 | H33: 0 | I33: 0 | J33: 0 | K33: 0 | L33: 0 | M33: 0 | N33: 0 | O33: 0 | P33: 0 | Q33: 0
C34: Control Valves, Modules, automation component | D34: ='IMPORT_OK Model'!E155/8 -> 397500 | E34: 0.2 | F34: =$D34*(1-$E34) -> 318000 | G34: 0 | H34: 0 | I34: 0 | J34: 0 | K34: 0 | L34: 0 | M34: 0 | N34: 0 | O34: 0 | P34: 0 | Q34: 0
B35: Oven
C36: Harbison-Walker (Refractory) | D36: ='IMPORT_OK Model'!E157/8 -> 180000 | E36: 0.2 | G36: =$D36*(1-$E36)/2 -> 72000 | H36: =$D36*(1-$E36)/2 -> 72000 | I36: 0 | J36: 0 | K36: 0 | L36: 0 | M36: 0 | N36: 0 | O36: 0 | P36: 0 | Q36: 0
C37: GTI-Engineering (Eclipse Burner and controls) | D37: ='IMPORT_OK Model'!E158/8 -> 357500 | E37: 0.2 | F37: =$D37*(1-$E37)/3 -> 95333.333 | G37: =$D37*(1-$E37)/3 -> 95333.333 | H37: =$D37*(1-$E37)/3 -> 95333.333 | I37: 0 | J37: 0 | K37: 0 | L37: 0 | M37: 0 | N37: 0 | O37: 0 | P37: 0 | Q37: 0
C38: Exothermics (Air to Air heat exchanger) | D38: ='IMPORT_OK Model'!E159/8 -> 265000 | E38: 0.2 | F38: =$D38*(1-$E38)/3 -> 70666.667 | G38: =$D38*(1-$E38)/3 -> 70666.667 | H38: =$D38*(1-$E38)/3 -> 70666.667 | I38: 0 | J38: 0 | K38: 0 | L38: 0 | M38: 0 | N38: 0 | O38: 0 | P38: 0 | Q38: 0
C39: Hubbel Water heater | D39: ='IMPORT_OK Model'!E160/8 -> 262500 | E39: 0.25 | F39: =$D39*(1-$E39)/3 -> 65625 | G39: =$D39*(1-$E39)/3 -> 65625 | H39: =$D39*(1-$E39)/3 -> 65625 | I39: 0 | J39: 0 | K39: 0 | L39: 0 | M39: 0 | N39: 0 | O39: 0 | P39: 0 | Q39: 0
C40: Emerson Thermal Couplers | D40: ='IMPORT_OK Model'!E161/8 -> 120000 | E40: 0.2 | F40: =$D40*(1-$E40)/3 -> 32000 | G40: =$D40*(1-$E40)/3 -> 32000 | H40: =$D40*(1-$E40)/3 -> 32000 | I40: 0 | J40: 0 | K40: 0 | L40: 0 | M40: 0 | N40: 0 | O40: 0 | P40: 0 | Q40: 0
B41: Reactor
C42: Cappco Fabricators (rolling and endplates) | D42: ='IMPORT_OK Model'!E163/8 -> 120000 | E42: 0.2 | F42: =$D42*(1-$E42)/3 -> 32000 | G42: =$D42*(1-$E42)/3 -> 32000 | H42: =$D42*(1-$E42)/3 -> 32000 | I42: 0 | J42: 0 | K42: 0 | L42: 0 | M42: 0 | N42: 0 | O42: 0 | P42: 0 | Q42: 0
C43: O&D Manufacturing (Brass seals and Bearings) | D43: ='IMPORT_OK Model'!E164/8 -> 120000 | E43: 0.2 | F43: =$D43*(1-$E43)/3 -> 32000 | G43: =$D43*(1-$E43)/3 -> 32000 | H43: =$D43*(1-$E43)/3 -> 32000 | I43: 0 | J43: 0 | K43: 0 | L43: 0 | M43: 0 | N43: 0 | O43: 0 | P43: 0 | Q43: 0
...

Sheet Sheet1
A1: Summary
C2: Category | D2: Total | F2: 1 | G2: 2 | H2: 3 | I2: 4 | J2: 5 | K2: 6 | L2: 7 | M2: 8 | N2: 9 | O2: 10 | P2: 11 | Q2: 12
C3: Equipment & Materials | D3: 5438875 | F3: 3228958.3 | G3: 1227958.3 | H3: 981958.33 | I3: 0 | J3: 0 | K3: 0 | L3: 0 | M3: 0 | N3: 0 | O3: 0 | P3: 0 | Q3: 0
C4: Facilities & Auxillary Support Systems | D4: 3674050 | F4: 1309683.3 | G4: 994683.33 | H4: 994683.33 | I4: 375000 | J4: 0 | K4: 0 | L4: 0 | M4: 0 | N4: 0 | O4: 0 | P4: 0 | Q4: 0
C5: Operating Costs | D5: 720500 | F5: 91450 | G5: 27950 | H5: 27950 | I5: 27950 | J5: 27950 | K5: 204016.67 | L5: 144616.67 | M5: 144616.67 | N5: 6000 | O5: 6000 | P5: 6000 | Q5: 6000
C6: Professional Services | D6: 401400 | F6: 364550 | G6: 4550 | H6: 4550 | I6: 4550 | J6: 9550 | K6: 4550 | L6: 4550 | M6: 4550 | N6: 0 | O6: 0 | P6: 0 | Q6: 0
C7: Workforce - Role - Pay Rate | D7: 2775367.6 | F7: 338436.18 | G7: 338436.18 | H7: 338436.18 | I7: 338436.18 | J7: 355405.72 | K7: 355405.72 | L7: 355405.72 | M7: 355405.72 | N7: 0 | O7: 0 | P7: 0 | Q7: 0
C9: Total Cost Build 1 SENS Processor | D9: 13010193 | F9: 5333077.9 | G9: 2593577.9 | H9: 2347577.9 | I9: 745936.18 | J9: 392905.72 | K9: 563972.39 | L9: 504572.39 | M9: 504572.39 | N9: 6000 | O9: 6000 | P9: 6000 | Q9: 6000
A12: Equipment & Materials
B13: Category | C13: Item | D13: Per Unit (Imported) | E13: Disc Rate | F13: 1 | G13: 2 | H13: 3 | I13: 4 | J13: 5 | K13: 6 | L13: 7 | M13: 8 | N13: 9 | O13: 10 | P13: 11 | Q13: 12
B14: Equipment & Materials
C15: Pack column, demister, liquid ring | D15: 233125 | E15: 0.2 | F15: 62166.667 | G15: 62166.667 | H15: 62166.667 | I15: 0 | J15: 0 | K15: 0 | L15: 0 | M15: 0 | N15: 0 | O15: 0 | P15: 0 | Q15: 0
C16: Ovens | D16: 609375 | E16: 0.2 | F16: 162500 | G16: 162500 | H16: 162500 | I16: 0 | J16: 0 | K16: 0 | L16: 0 | M16: 0 | N16: 0 | O16: 0 | P16: 0 | Q16: 0
C17: Pipe, fittings, auger tube shafts | D17: 516250 | E17: 0.2 | F17: 137666.67 | G17: 137666.67 | H17: 137666.67 | I17: 0 | J17: 0 | K17: 0 | L17: 0 | M17: 0 | N17: 0 | O17: 0 | P17: 0 | Q17: 0
C18: Weight hopper feed system | D18: 582500 | E18: 0.2 | F18: 155333.33 | G18: 155333.33 | H18: 155333.33 | I18: 0 | J18: 0 | K18: 0 | L18: 0 | M18: 0 | N18: 0 | O18: 0 | P18: 0 | Q18: 0
B19: National Tube sales
C20: Auger tubes | D20: 330000 | E20: 0.2 | F20: 132000 | G20: 132000 | H20: 0 | I20: 0 | J20: 0 | K20: 0 | L20: 0 | M20: 0 | N20: 0 | O20: 0 | P20: 0 | Q20: 0
B21: Thomas Conveyor
C22: Auger flights | D22: 160000 | E22: 0.2 | F22: 64000 | G22: 64000 | H22: 0 | I22: 0 | J22: 0 | K22: 0 | L22: 0 | M22: 0 | N22: 0 | O22: 0 | P22: 0 | Q22: 0
C23: Tapered Screw for weigh hopper | D23: 125000 | E23: 0.2 | F23: 50000 | G23: 50000 | H23: 0 | I23: 0 | J23: 0 | K23: 0 | L23: 0 | M23: 0 | N23: 0 | O23: 0 | P23: 0 | Q23: 0
B24: Controls, motors and pumps
C25: Control Automation Component | D25: 478125 | E25: 0.2 | F25: 382500 | G25: 0 | H25: 0 | I25: 0 | J25: 0 | K25: 0 | L25: 0 | M25: 0 | N25: 0 | O25: 0 | P25: 0 | Q25: 0
C26: Motors, gearboxes, drives, bucket elevators | D26: 356250 | E26: 0.2 | F26: 285000 | G26: 0 | H26: 0 | I26: 0 | J26: 0 | K26: 0 | L26: 0 | M26: 0 | N26: 0 | O26: 0 | P26: 0 | Q26: 0
C27: Chiller Contols & Electrical | D27: 197500 | E27: 0.2 | F27: 158000 | G27: 0 | H27: 0 | I27: 0 | J27: 0 | K27: 0 | L27: 0 | M27: 0 | N27: 0 | O27: 0 | P27: 0 | Q27: 0
C28: Myers (Flapper valves) | D28: 112500 | E28: 0.2 | F28: 90000 | G28: 0 | H28: 0 | I28: 0 | J28: 0 | K28: 0 | L28: 0 | M28: 0 | N28: 0 | O28: 0 | P28: 0 | Q28: 0
C29: Myers Aubrey (Steam, and Gas Processing control valves) | D29: 335625 | E29: 0.2 | F29: 268500 | G29: 0 | H29: 0 | I29: 0 | J29: 0 | K29: 0 | L29: 0 | M29: 0 | N29: 0 | O29: 0 | P29: 0 | Q29: 0
C30: Myers Aubrey (Flow meters) | D30: 170000 | E30: 0.2 | F30: 136000 | G30: 0 | H30: 0 | I30: 0 | J30: 0 | K30: 0 | L30: 0 | M30: 0 | N30: 0 | O30: 0 | P30: 0 | Q30: 0
C31: Automatic Pump (Vacuum and Oil Water Separator) | D31: 172500 | E31: 0.2 | F31: 138000 | G31: 0 | H31: 0 | I31: 0 | J31: 0 | K31: 0 | L31: 0 | M31: 0 | N31: 0 | O31: 0 | P31: 0 | Q31: 0
C32: Roberts & Spencer (Pressure transmitters, Vac Control Valves, level indicators) | D32: 168125 | E32: 0.2 | F32: 134500 | G32: 0 | H32: 0 | I32: 0 | J32: 0 | K32: 0 | L32: 0 | M32: 0 | N32: 0 | O32: 0 | P32: 0 | Q32: 0
C33: Switch Gear and Generator | D33: 203125 | E33: 0.2 | F33: 162500 | G33: 0 | H33: 0 | I33: 0 | J33: 0 | K33: 0 | L33: 0 | M33: 0 | N33: 0 | O33: 0 | P33: 0 | Q33: 0
C34: Control Valves, Modules, automation component | D34: 397500 | E34: 0.2 | F34: 318000 | G34: 0 | H34: 0 | I34: 0 | J34: 0 | K34: 0 | L34: 0 | M34: 0 | N34: 0 | O34: 0 | P34: 0 | Q34: 0
B35: Oven
C36: Harbison-Walker (Refractory) | D36: 180000 | E36: 0.2 | G36: 72000 | H36: 72000 | I36: 0 | J36: 0 | K36: 0 | L36: 0 | M36: 0 | N36: 0 | O36: 0 | P36: 0 | Q36: 0
C37: GTI-Engineering (Eclipse Burner and controls) | D37: 357500 | E37: 0.2 | F37: 95333.333 | G37: 95333.333 | H37: 95333.333 | I37: 0 | J37: 0 | K37: 0 | L37: 0 | M37: 0 | N37: 0 | O37: 0 | P37: 0 | Q37: 0
C38: Exothermics (Air to Air heat exchanger) | D38: 265000 | E38: 0.2 | F38: 70666.667 | G38: 70666.667 | H38: 70666.667 | I38: 0 | J38: 0 | K38: 0 | L38: 0 | M38: 0 | N38: 0 | O38: 0 | P38: 0 | Q38: 0
C39: Hubbel Water heater | D39: 262500 | E39: 0.25 | F39: 65625 | G39: 65625 | H39: 65625 | I39: 0 | J39: 0 | K39: 0 | L39: 0 | M39: 0 | N39: 0 | O39: 0 | P39: 0 | Q39: 0
C40: Emerson Thermal Couplers | D40: 120000 | E40: 0.2 | F40: 32000 | G40: 32000 | H40: 32000 | I40: 0 | J40: 0 | K40: 0 | L40: 0 | M40: 0 | N40: 0 | O40: 0 | P40: 0 | Q40: 0
B41: Reactor
C42: Cappco Fabricators (rolling and endplates) | D42: 120000 | E42: 0.2 | F42: 32000 | G42: 32000 | H42: 32000 | I42: 0 | J42: 0 | K42: 0 | L42: 0 | M42: 0 | N42: 0 | O42: 0 | P42: 0 | Q42: 0
C43: O&D Manufacturing (Brass seals and Bearings) | D43: 120000 | E43: 0.2 | F43: 32000 | G43: 32000 | H43: 32000 | I43: 0 | J43: 0 | K43: 0 | L43: 0 | M43: 0 | N43: 0 | O43: 0 | P43: 0 | Q43: 0
...

Sheet IMPORT_OK Model
A4: =[1]ModelDescription!A4 -> Economic Forecasting Model
A5: =[1]ModelDescription!C6 -> Oklahoma TDF Processing Site Economic Evaluation All Phase V4
B6: Period | F6: =[1]Assumptions!B56 -> 1 | G6: =[1]Assumptions!C56 -> 2 | H6: =[1]Assumptions!D56 -> 3 | I6: =[1]Assumptions!E56 -> 4 | J6: =[1]Assumptions!F56 -> 5 | K6: =[1]Assumptions!G56 -> 6 | L6: =[1]Assumptions!H56 -> 7 | M6: =[1]Assumptions!I56 -> 8 | ... BM6: =[1]Assumptions!BI56 -> 60
B7: Year | F7: =[1]Assumptions!B57 -> 2023 | G7: =[1]Assumptions!C57 -> 2023 | H7: =[1]Assumptions!D57 -> 2023 | I7: =[1]Assumptions!E57 -> 2024 | J7: =[1]Assumptions!F57 -> 2024 | K7: =[1]Assumptions!G57 -> 2024 | L7: =[1]Assumptions!H57 -> 2024 | M7: =[1]Assumptions!I57 -> 2024 | ... BM7: =[1]Assumptions!BI57 -> 2028
B8: Month | F8: =[1]Assumptions!B58 -> October | G8: =[1]Assumptions!C58 -> November | H8: =[1]Assumptions!D58 -> Dec | I8: =[1]Assumptions!E58 -> Jan | J8: =[1]Assumptions!F58 -> Feb | K8: =[1]Assumptions!G58 -> Mar | L8: =[1]Assumptions!H58 -> April | M8: =[1]Assumptions!I58 -> May | ... BM8: =[1]Assumptions!BI58 -> Sept
B9: Days | F9: =[1]Assumptions!B60 -> 31 | G9: =[1]Assumptions!C60 -> 30 | H9: =[1]Assumptions!D60 -> 31 | I9: =[1]Assumptions!E60 -> 31 | J9: =[1]Assumptions!F60 -> 29 | K9: =[1]Assumptions!G60 -> 31 | L9: =[1]Assumptions!H60 -> 30 | M9: =[1]Assumptions!I60 -> 31 | ... BM9: =[1]Assumptions!BI60 -> 30
B10: Revenue | C10: R | E10: =SUM(F10:BM10) -> 6.3688762e+08 | F10: =SUMPRODUCT((F$20:F$343)*($C$20:$C$343=$C10)) -> 0 | G10: =SUMPRODUCT((G$20:G$343)*($C$20:$C$343=$C10)) -> 0 | H10: =SUMPRODUCT((H$20:H$343)*($C$20:$C$343=$C10)) -> 0 | I10: =SUMPRODUCT((I$20:I$343)*($C$20:$C$343=$C10)) -> 0 | J10: =SUMPRODUCT((J$20:J$343)*($C$20:$C$343=$C10)) -> 0 | K10: =SUMPRODUCT((K$20:K$343)*($C$20:$C$343=$C10)) -> 0 | L10: =SUMPRODUCT((L$20:L$343)*($C$20:$C$343=$C10)) -> 25920 | M10: =SUMPRODUCT((M$20:M$343)*($C$20:$C$343=$C10)) -> 147312 | ... BM10: =SUMPRODUCT((BM$20:BM$343)*($C$20:$C$343=$C10)) -> 17355822
B11: Capital Investment ( Loan) | C11: L | E11: =SUM(F11:BM11) -> 86000000 | F11: 43000000 | G11: 0 | H11: 0 | I11: 18000000 | J11: 0 | K11: 0 | L11: 20000000 | M11: 0 | N11: =SUMPRODUCT((N$20:N$343)*($C$20:$C$343=$C11)) -> 0 | O11: =SUMPRODUCT((O$20:O$343)*($C$20:$C$343=$C11)) -> 5000000 | P11: 0 | Q11: =SUMPRODUCT((Q$20:Q$343)*($C$20:$C$343=$C11)) -> 0 | R11: =SUMPRODUCT((R$20:R$343)*($C$20:$C$343=$C11)) -> 0 | S11: =SUMPRODUCT((S$20:S$343)*($C$20:$C$343=$C11)) -> 0 | T11: =SUMPRODUCT((T$20:T$343)*($C$20:$C$343=$C11)) -> 0 | U11: =SUMPRODUCT((U$20:U$343)*($C$20:$C$343=$C11)) -> 0 | V11: =SUMPRODUCT((V$20:V$343)*($C$20:$C$343=$C11)) -> 0 | W11: =SUMPRODUCT((W$20:W$343)*($C$20:$C$343=$C11)) -> 0 | X11: =SUMPRODUCT((X$20:X$343)*($C$20:$C$343=$C11)) -> 0 | ... BM11: =SUMPRODUCT((BM$20:BM$343)*($C$20:$C$343=$C11)) -> 0
B12: Costs | C12: C | E12: =SUM(F12:BM12) -> 1.648922e+08 | F12: =SUMPRODUCT((F$20:F$343)*($C$20:$C$343=$C12)) -> 4450000 | G12: =SUMPRODUCT((G$20:G$343)*($C$20:$C$343=$C12)) -> 0 | H12: =SUMPRODUCT((H$20:H$343)*($C$20:$C$343=$C12)) -> 0 | I12: =SUMPRODUCT((I$20:I$343)*($C$20:$C$343=$C12)) -> 0 | J12: =SUMPRODUCT((J$20:J$343)*($C$20:$C$343=$C12)) -> 0 | K12: =SUMPRODUCT((K$20:K$343)*($C$20:$C$343=$C12)) -> 0 | L12: =SUMPRODUCT((L$20:L$343)*($C$20:$C$343=$C12)) -> 0 | M12: =SUMPRODUCT((M$20:M$343)*($C$20:$C$343=$C12)) -> 0 | ... BM12: =SUMPRODUCT((BM$20:BM$343)*($C$20:$C$343=$C12)) -> 2333862.2
B13: Business Overhead | C13: O | E13: =SUM(F13:BM13) -> 19325434 | F13: =SUMPRODUCT((F$20:F$343)*($C$20:$C$343=$C13)) -> 0 | G13: =SUMPRODUCT((G$20:G$343)*($C$20:$C$343=$C13)) -> 0 | H13: =SUMPRODUCT((H$20:H$343)*($C$20:$C$343=$C13)) -> 0 | I13: =SUMPRODUCT((I$20:I$343)*($C$20:$C$343=$C13)) -> 0 | J13: =SUMPRODUCT((J$20:J$343)*($C$20:$C$343=$C13)) -> 0 | K13: =SUMPRODUCT((K$20:K$343)*($C$20:$C$343=$C13)) -> 0 | L13: =SUMPRODUCT((L$20:L$343)*($C$20:$C$343=$C13)) -> 48000 | M13: =SUMPRODUCT((M$20:M$343)*($C$20:$C$343=$C13)) -> 48000 | ... BM13: =SUMPRODUCT((BM$20:BM$343)*($C$20:$C$343=$C13)) -> 406637.2
B14: Capital Costs | C14: CAP | E14: =SUM(F14:BM14) -> 1.2193606e+08 | F14: =SUMPRODUCT((F$20:F$343)*($C$20:$C$343=$C14)) -> 14011030 | G14: =SUMPRODUCT((G$20:G$343)*($C$20:$C$343=$C14)) -> 11299454 | H14: =SUMPRODUCT((H$20:H$343)*($C$20:$C$343=$C14)) -> 10141630 | I14: =SUMPRODUCT((I$20:I$343)*($C$20:$C$343=$C14)) -> 4586380 | J14: =SUMPRODUCT((J$20:J$343)*($C$20:$C$343=$C14)) -> 8715230.4 | K14: =SUMPRODUCT((K$20:K$343)*($C$20:$C$343=$C14)) -> 3189780 | L14: =SUMPRODUCT((L$20:L$343)*($C$20:$C$343=$C14)) -> 8483088 | M14: =SUMPRODUCT((M$20:M$343)*($C$20:$C$343=$C14)) -> 3523960.8 | ... BM14: =SUMPRODUCT((BM$20:BM$343)*($C$20:$C$343=$C14)) -> 173830
B15: Loan Payment | C15: LP | E15: =SUM(F15:BM15) -> 86000000 | F15: =SUMPRODUCT((F$20:F$343)*($C$20:$C$343=$C15)) -> 0 | G15: =SUMPRODUCT((G$20:G$343)*($C$20:$C$343=$C15)) -> 0 | H15: =SUMPRODUCT((H$20:H$343)*($C$20:$C$343=$C15)) -> 0 | I15: =SUMPRODUCT((I$20:I$343)*($C$20:$C$343=$C15)) -> 0 | J15: =SUMPRODUCT((J$20:J$343)*($C$20:$C$343=$C15)) -> 0 | K15: =SUMPRODUCT((K$20:K$343)*($C$20:$C$343=$C15)) -> 0 | L15: =SUMPRODUCT((L$20:L$343)*($C$20:$C$343=$C15)) -> 0 | M15: =SUMPRODUCT((M$20:M$343)*($C$20:$C$343=$C15)) -> 0 | ... X15: =SUMPRODUCT((X$20:X$343)*($C$20:$C$343=$C15)) -> 0 | Y15: 0 | Z15: 5000000 | AA15: 5000000 | AB15: 5000000 | AC15: 5000000 | AD15: 5000000 | AE15: 5000000 | AF15: 5000000 | AG15: 5000000 | AH15: 5000000 | AI15: 5000000 | AJ15: 5000000 | AK15: 5000000 | AL15: 5000000 | AM15: 5000000 | AN15: 5000000 | AO15: 5000000 | AP15: 6000000 | AQ15: 0 | AR15: 0 | AS15: =SUMPRODUCT((AS$20:AS$343)*($C$20:$C$343=$C15)) -> 0 | AT15: 0 | AU15: =SUMPRODUCT((AU$20:AU$343)*($C$20:$C$343=$C15)) -> 0 | AV15: =SUMPRODUCT((AV$20:AV$343)*($C$20:$C$343=$C15)) -> 0 | AW15: 0 | AX15: =SUMPRODUCT((AX$20:AX$343)*($C$20:$C$343=$C15)) -> 0 | AY15: =SUMPRODUCT((AY$20:AY$343)*($C$20:$C$343=$C15)) -> 0 | AZ15: 0 | BA15: =SUMPRODUCT((BA$20:BA$343)*($C$20:$C$343=$C15)) -> 0 | BB15: =SUMPRODUCT((BB$20:BB$343)*($C$20:$C$343=$C15)) -> 0 | BC15: 0 | BD15: =SUMPRODUCT((BD$20:BD$343)*($C$20:$C$343=$C15)) -> 0 | BE15: =SUMPRODUCT((BE$20:BE$343)*($C$20:$C$343=$C15)) -> 0 | BF15: 0 | BG15: =SUMPRODUCT((BG$20:BG$343)*($C$20:$C$343=$C15)) -> 0 | BH15: =SUMPRODUCT((BH$20:BH$343)*($C$20:$C$343=$C15)) -> 0 | BI15: 0 | BJ15: =SUMPRODUCT((BJ$20:BJ$343)*($C$20:$C$343=$C15)) -> 0 | BK15: =SUMPRODUCT((BK$20:BK$343)*($C$20:$C$343=$C15)) -> 0 | BL15: =SUMPRODUCT((BL$20:BL$343)*($C$20:$C$343=$C15)) -> 0 | BM15: =SUMPRODUCT((BM$20:BM$343)*($C$20:$C$343=$C15)) -> 0
B16: Depreciation | C16: DEP | E16: =SUM(F16:BM16) -> 85444192 | F16: =SUMPRODUCT((F$20:F$343)*($C$20:$C$343=$C16)) -> 0 | G16: =SUMPRODUCT((G$20:G$343)*($C$20:$C$343=$C16)) -> 0 | H16: =SUMPRODUCT((H$20:H$343)*($C$20:$C$343=$C16)) -> 0 | I16: =SUMPRODUCT((I$20:I$343)*($C$20:$C$343=$C16)) -> 0 | J16: =SUMPRODUCT((J$20:J$343)*($C$20:$C$343=$C16)) -> 0 | K16: =SUMPRODUCT((K$20:K$343)*($C$20:$C$343=$C16)) -> 0 | L16: =SUMPRODUCT((L$20:L$343)*($C$20:$C$343=$C16)) -> 0 | M16: =SUMPRODUCT((M$20:M$343)*($C$20:$C$343=$C16)) -> 0 | N16: =SUMPRODUCT((N$20:N$343)*($C$20:$C$343=$C16)) -> 0 | O16: {=SUMPRODUCT((O$20:O$343)*($C$20:$C$343=$C16))} -> 1369307.7 | P16: =SUMPRODUCT((P$20:P$343)*($C$20:$C$343=$C16)) -> 1369307.7 | Q16: =SUMPRODUCT((Q$20:Q$343)*($C$20:$C$343=$C16)) -> 1369307.7 | R16: =SUMPRODUCT((R$20:R$343)*($C$20:$C$343=$C16)) -> 1369307.7 | S16: =SUMPRODUCT((S$20:S$343)*($C$20:$C$343=$C16)) -> 1369307.7 | T16: =SUMPRODUCT((T$20:T$343)*($C$20:$C$343=$C16)) -> 1369307.7 | U16: =SUMPRODUCT((U$20:U$343)*($C$20:$C$343=$C16)) -> 1369307.7 | V16: =SUMPRODUCT((V$20:V$343)*($C$20:$C$343=$C16)) -> 1369307.7 | W16: =SUMPRODUCT((W$20:W$343)*($C$20:$C$343=$C16)) -> 1369307.7 | ... BH16: =SUMPRODUCT((BH$20:BH$343)*($C$20:$C$343=$C16)) -> 1889624.4 | BI16: {=SUMPRODUCT((BI$20:BI$343)*($C$20:$C$343=$C16))} -> 1889624.4 | BJ16: =SUMPRODUCT((BJ$20:BJ$343)*($C$20:$C$343=$C16)) -> 1889624.4 | BK16: =SUMPRODUCT((BK$20:BK$343)*($C$20:$C$343=$C16)) -> 1889624.4 | BL16: =SUMPRODUCT((BL$20:BL$343)*($C$20:$C$343=$C16)) -> 1889624.4 | BM16: =SUMPRODUCT((BM$20:BM$343)*($C$20:$C$343=$C16)) -> 1889624.4
B17: Monthly Profit/Loss (EBITDA) | F17: =SUM(F10:F11)-SUM(F12:F15) -> 24538970 | G17: =SUM(G10:G11)-SUM(G12:G15) -> -11299454 | H17: =SUM(H10:H11)-SUM(H12:H15) -> -10141630 | I17: =SUM(I10:I11)-SUM(I12:I15) -> 13413620 | J17: =SUM(J10:J11)-SUM(J12:J15) -> -8715230.4 | K17: =SUM(K10:K11)-SUM(K12:K15) -> -3189780 | L17: =SUM(L10:L11)-SUM(L12:L15) -> 11494832 | M17: =SUM(M10:M11)-SUM(M12:M15) -> -3424648.8 | ... BM17: =SUM(BM10:BM11)-SUM(BM12:BM15) -> 14441493
B18: Project Cumulative Cash Flow | F18: =E18+F17 -> 24538970 | G18: =F18+G17 -> 13239516 | H18: =G18+H17 -> 3097886 | I18: =H18+I17 -> 16511506 | J18: =I18+J17 -> 7796275.6 | K18: =J18+K17 -> 4606495.6 | L18: =K18+L17 -> 16101328 | M18: =L18+M17 -> 12676679 | ... BM18: =BL18+BM17 -> 3.3073393e+08
A22: Project Capital
B23: Capital Investment USD | C23: L | E23: =SUM(F23:BM23) -> 86000000 | F23: 43000000 | G23: 0 | H23: 0 | I23: 18000000 | J23: 0 | K23: 0 | L23: 20000000 | M23: 0 | O23: 5000000 | P23: 0
B24: Cash Draw | E24: =SUM(F24:BM24) -> 86000000 | F24: 43000000 | G24: 0 | H24: 0 | I24: 18000000 | J24: 0 | K24: 0 | L24: 20000000 | M24: 0 | O24: 5000000 | P24: 0
E25: =SUM(F25:BM25) -> 0
B26: Loan Payments | C26: LP | E26: =SUM(F26:BM26) -> 0 | AC26: 0 | AE26: 0 | AH26: 0 | AK26: 0 | AN26: 0 | AQ26: 0 | AT26: 0 | AW26: 0 | AZ26: 0 | BC26: 0
A29: Investment Costs
B30: Prepaid Expences | E30: =SUM(F30:BM30) -> 0 | F30: 0
B31: Past accumulatded Cost Pay Out | E31: =SUM(F31:BM31) -> 4200000 | F31: 4200000
B32: Consultant Introduction Fee | E32: =SUM(F32:BM32) -> 250000 | F32: 250000 | G32: 0 | H32: 0 | I32: 0 | J32: 0 | L32: 0 | O32: 0
B33: Interest (0.0% annual Interest) | D33: 0 | E33: =SUM(F33:BM33) -> 0 | O33: =-IPMT($D33/12,O6-$N6,$BM6-$N6,$F23,) -> 0 | P33: =-IPMT($D33/12,P6-$N6,$BM6-$N6,$F23,) -> 0 | Q33: =-IPMT($D33/12,Q6-$N6,$BM6-$N6,$F23,) -> 0 | R33: =-IPMT($D33/12,R6-$N6,$BM6-$N6,$F23,) -> 0 | S33: =-IPMT($D33/12,S6-$N6,$BM6-$N6,$F23,) -> 0 | T33: =-IPMT($D33/12,T6-$N6,$BM6-$N6,$F23,) -> 0 | U33: =-IPMT($D33/12,U6-$N6,$BM6-$N6,$F23,) -> 0 | V33: =-IPMT($D33/12,V6-$N6,$BM6-$N6,$F23,) -> 0 | ... BM33: =-IPMT($D33/12,BM6-$N6,$BM6-$N6,$F23,) -> 0
E34: =SUM(F34:BM34) -> 0 | AO34: =F25 -> 0
B35: Total Pre Development Costs | C35: C | D35: =E35/E23 -> 0.051744186 | E35: =SUM(F35:BM35) -> 4450000 | F35: =SUM(F30:F34) -> 4450000 | G35: =SUM(G30:G34) -> 0 | H35: =SUM(H30:H34) -> 0 | I35: =SUM(I30:I34) -> 0 | J35: =SUM(J30:J34) -> 0 | K35: =SUM(K30:K34) -> 0 | L35: =SUM(L30:L34) -> 0 | M35: =SUM(M30:M34) -> 0 | ... BM35: =SUM(BM30:BM34) -> 0
A37: Fulcrum Corporate Office ( Proportionate share to project)
B39: Executive Office (Edmonton)
B40: Fulcrum/FES - Office Equipment Security Expense (Furniture, Electronics, Software, Computers etc) * (PMT Plan) | E40: =SUM(F40:BM40) -> 0 | F40: 0 | G40: =F40 -> 0 | H40: =G40 -> 0 | I40: =H40 -> 0 | J40: =I40 -> 0 | K40: =J40 -> 0 | L40: =K40 -> 0 | M40: =L40 -> 0 | N40: =M40 -> 0 | ... Q40: =P40 -> 0
B41: Fulcrum - Auto Exp. | E41: =SUM(F41:BM41) -> 150000 | F41: 2500 | G41: =F41 -> 2500 | H41: =G41 -> 2500 | I41: =H41 -> 2500 | J41: =I41 -> 2500 | K41: =J41 -> 2500 | L41: =K41 -> 2500 | M41: =L41 -> 2500 | N41: =M41 -> 2500 | ... BM41: =BL41 -> 2500
B42: Fulcrum - Office Supplies | E42: =SUM(F42:BM42) -> 9000 | F42: 150 | G42: =F42 -> 150 | H42: =G42 -> 150 | I42: =H42 -> 150 | J42: =I42 -> 150 | K42: =J42 -> 150 | L42: =K42 -> 150 | M42: =L42 -> 150 | N42: =M42 -> 150 | ... BM42: =BL42 -> 150
B43: Fulcrum - Office Expenses | E43: =SUM(F43:BM43) -> 0 | F43: 0 | G43: =F43 -> 0 | H43: =G43 -> 0 | I43: =H43 -> 0 | J43: =I43 -> 0 | K43: =J43 -> 0 | L43: =K43 -> 0 | M43: =L43 -> 0 | N43: =M43 -> 0 | ... BM43: =BL43 -> 0
B44: Fulcrum - Salaries & Wages - Executive/ Administrative | E44: =SUM(F44:BM44) -> 3408000 | F44: 56800 | G44: =F44 -> 56800 | H44: =G44 -> 56800 | I44: =H44 -> 56800 | J44: =I44 -> 56800 | K44: =J44 -> 56800 | L44: =K44 -> 56800 | M44: =L44 -> 56800 | N44: =M44 -> 56800 | ... BM44: =BL44 -> 56800
B45: Fulcrum - Benefts | E45: =SUM(F45:BM45) -> 132000 | F45: 2200 | G45: =F45 -> 2200 | H45: =G45 -> 2200 | I45: =H45 -> 2200 | J45: =I45 -> 2200 | K45: =J45 -> 2200 | L45: =K45 -> 2200 | M45: =L45 -> 2200 | N45: =M45 -> 2200 | ... BM45: =BL45 -> 2200
B46: Fulcrum - Payroll Burden | E46: =SUM(F46:BM46) -> 708000 | F46: =SUM(F44:F45)*0.2 -> 11800 | G46: =F46 -> 11800 | H46: =G46 -> 11800 | I46: =H46 -> 11800 | J46: =I46 -> 11800 | K46: =J46 -> 11800 | L46: =K46 -> 11800 | M46: =L46 -> 11800 | N46: =M46 -> 11800 | ... BM46: =BL46 -> 11800
B47: Fulcrum - Office Rent Inc. CAC Costs | E47: =SUM(F47:BM47) -> 450000 | F47: 7500 | G47: =F47 -> 7500 | H47: =G47 -> 7500 | I47: =H47 -> 7500 | J47: =I47 -> 7500 | K47: =J47 -> 7500 | L47: =K47 -> 7500 | M47: =L47 -> 7500 | N47: =M47 -> 7500 | ... BM47: =BL47 -> 7500
B48: Fulcrum - Security Expense | E48: =SUM(F48:BM48) -> 0 | F48: 0 | G48: =F48 -> 0 | H48: =G48 -> 0 | I48: =H48 -> 0 | J48: =I48 -> 0 | K48: =J48 -> 0 | L48: =K48 -> 0 | M48: =L48 -> 0 | N48: =M48 -> 0 | ... BM48: =BL48 -> 0
B49: Fulcrum - Utilities: Telephone & Internet | E49: =SUM(F49:BM49) -> 36000 | F49: 600 | G49: =F49 -> 600 | H49: =G49 -> 600 | I49: =H49 -> 600 | J49: =I49 -> 600 | K49: =J49 -> 600 | L49: =K49 -> 600 | M49: =L49 -> 600 | N49: =M49 -> 600 | ... BM49: =BL49 -> 600
B50: Fulcrum - Utilities: Gas | E50: =SUM(F50:BM50) -> 21000 | F50: 350 | G50: =F50 -> 350 | H50: =G50 -> 350 | I50: =H50 -> 350 | J50: =I50 -> 350 | K50: =J50 -> 350 | L50: =K50 -> 350 | M50: =L50 -> 350 | N50: =M50 -> 350 | ... BM50: =BL50 -> 350
...
