Workbook
Name FV: #REF!
Name FV: #REF!
Name FVV: #REF!
Name FVVV: #REF!

Sheet ModelDescription
A2: Economic Forecasting Model
A4: PLAN: | C4: Noble, OK 6 Processor Facility - Series A + Series B
B6: Main Assumptions / Planning Contingencies
B7: 1 | C7: Economics run for a period of 15 years
B8: =1+B7 -> 2 | C8: ="Crumb rubber purchase price assumed to be $"&Assumptions!$D$13&"/lb - market price is $.10-.15/lb" -> Crumb rubber purchase price assumed to be $0.1/lb - market price is $.10-.15/lb
B9: =1+B8 -> 3 | C9: Crumb rubber product assumed to have composition that allows for processing splits of 45% solvent/45% carbon black/10% process gas by weight
B10: =1+B9 -> 4 | C10: ="Solvent based on $"&Assumptions!$D$16&"/gal - competitive market price is approx. $10-18/gal" -> Solvent based on $8/gal - competitive market price is approx. $10-18/gal
B11: =1+B10 -> 5 | C11: ="Carbon Black based on $"&Assumptions!D17&"/lb - competitive market price is approx. $.55/lb+" -> Carbon Black based on $0.5/lb - competitive market price is approx. $.55/lb+
B12: =1+B11 -> 6 | C12: ="RNG is priced at $"&Assumptions!D18&"/MCF - wholesale market price fluctuates between $2-5/MCF" -> RNG is priced at $1.5/MCF - wholesale market price fluctuates between $2-5/MCF
B13: =1+B12 -> 7 | C13: Series A $15 unlocks 1 machine - for Series A specific finances, turn dial below to "1 Machine"; Series B $110M unlocks additional 5 machines and site buildout - for complete project finances, turn dial below to "6 Machine"
B14: =1+B13 -> 8 | C14: $125 Million in total used to purchase and develop land, carbon handling, gas handling, construct facilities and 6 TiPs processors and related storage with 10% project capex buffer; construction budget has 20% contingency built in; machine capex has 30% buffer
B15: =1+B14 -> 9 | C15: External Utility Expense Utilized on Operating Costs - Will be reduced by 95% utilizing own power generation and Gas from Process at full operation
B16: =1+B17 -> 11 | C16: 48 tons per day production for each TiPs unit; Total of 6 Processors at full operation
B17: =1+B15 -> 10 | C17: ="Plant availability is set at "&TEXT(Assumptions!D36,"0.0%")&", where operation capacity is expected to be 90%+" -> Plant availability is set at 0.0%, where operation capacity is expected to be 90%+
B18: =1+B16 -> 12 | C18: Capital assets are depreciated over 15 years; depreciation begins for machine 1 when it is operational; depreciation begins on machines 2-6 when machine 6 is operational
B19: =1+B18 -> 13 | C19: No shredding requirement as crumb feed is purchased from local supplier
B20: =1+B19 -> 14 | C20: Machine build time assumed to be 8 months; actual expected to be 5 months
B21: =1+B20 -> 15 | C21: Sensitivity Analysis performed on pricing for crumb rubber, carbon black, solvent, as well as personnel costs and product cut
C23: 1 Machine / 6 Machine Switch | D23: 1 Machine
C25: Economic Highlights (at the end of 15 years)
C26: Revenue | D26: =Economics!T7 -> 3.105788e+08
C27: EBITDA | D27: =Economics!T11 -> 1.8174581e+08
C28: Sales Margin | D28: =Economics!U9 -> 0.64389453
C29: Fixed Asset Value | D29: =Economics!R27 -> 1037487
C30: Investment | D30: =Economics!D20 -> 15000000
C31: Net Present Value (NPV) | D31: =Economics!R29 -> 14574636
C33: Internal Rate of Return (IRR) Year 5 - Series A Investment | D33: =Economics!H34 -> 0.19504061
C34: Internal Rate of Return (IRR) Year 15 - Series A Investment | D34: =Economics!R34 -> 0.38133255

Sheet Sheet5

Sheet Sheet6

Sheet Economics
A2: =ModelDescription!A2 -> Economic Forecasting Model
A3: =ModelDescription!C4 -> Noble, OK 6 Processor Facility - Series A + Series B
B5: Year | D5: =MthCashSum!F6 -> 2026 | E5: =D5+1 -> 2027 | F5: =E5+1 -> 2028 | G5: =F5+1 -> 2029 | H5: =G5+1 -> 2030 | I5: =H5+1 -> 2031 | J5: =I5+1 -> 2032 | K5: =J5+1 -> 2033 | L5: =K5+1 -> 2034 | ... R5: =Q5+1 -> 2040 | T5: Total
B6: Annual Period | D6: 1 | E6: =D6+1 -> 2 | F6: =E6+1 -> 3 | G6: =F6+1 -> 4 | H6: =G6+1 -> 5 | I6: =H6+1 -> 6 | J6: =I6+1 -> 7 | K6: =J6+1 -> 8 | L6: =K6+1 -> 9 | ... R6: =Q6+1 -> 15
B7: Revenue Forward | C7: R | D7: {=SUMPRODUCT((D$39:D$82)*($C$39:$C$82=$C7))} -> 8947438.7 | E7: {=SUMPRODUCT((E$39:E$82)*($C$39:$C$82=$C7))} -> 21545097 | F7: =SUMPRODUCT((F$39:F$82)*($C$39:$C$82=$C7)) -> 21545097 | G7: =SUMPRODUCT((G$39:G$82)*($C$39:$C$82=$C7)) -> 21545097 | H7: =SUMPRODUCT((H$39:H$82)*($C$39:$C$82=$C7)) -> 21545097 | I7: =SUMPRODUCT((I$39:I$82)*($C$39:$C$82=$C7)) -> 21545097 | J7: =SUMPRODUCT((J$39:J$82)*($C$39:$C$82=$C7)) -> 21545097 | K7: =SUMPRODUCT((K$39:K$82)*($C$39:$C$82=$C7)) -> 21545097 | L7: =SUMPRODUCT((L$39:L$82)*($C$39:$C$82=$C7)) -> 21545097 | M7: =SUMPRODUCT((M$39:M$82)*($C$39:$C$82=$C7)) -> 21545097 | ... R7: =SUMPRODUCT((R$39:R$82)*($C$39:$C$82=$C7)) -> 21545097 | T7: =SUM(D7:R7) -> 3.105788e+08
B8: Costs | C8: C | D8: {=-SUMPRODUCT((D$39:D$82)*($C$39:$C$82=$C8))} -> -3215165.3 | E8: =-SUMPRODUCT((E$39:E$82)*($C$39:$C$82=$C8)) -> -7670260.4 | F8: =-SUMPRODUCT((F$39:F$82)*($C$39:$C$82=$C8)) -> -7670260.4 | G8: =-SUMPRODUCT((G$39:G$82)*($C$39:$C$82=$C8)) -> -7670260.4 | H8: =-SUMPRODUCT((H$39:H$82)*($C$39:$C$82=$C8)) -> -7670260.4 | I8: =-SUMPRODUCT((I$39:I$82)*($C$39:$C$82=$C8)) -> -7670260.4 | J8: =-SUMPRODUCT((J$39:J$82)*($C$39:$C$82=$C8)) -> -7670260.4 | K8: =-SUMPRODUCT((K$39:K$82)*($C$39:$C$82=$C8)) -> -7670260.4 | L8: =-SUMPRODUCT((L$39:L$82)*($C$39:$C$82=$C8)) -> -7670260.4 | ... R8: =-SUMPRODUCT((R$39:R$82)*($C$39:$C$82=$C8)) -> -7670260.4 | T8: =SUM(D8:R8) -> -1.1059881e+08
B9: Job Profit | D9: =D7+D8 -> 5732273.4 | E9: =E7+E8 -> 13874837 | F9: =F7+F8 -> 13874837 | G9: =G7+G8 -> 13874837 | H9: =H7+H8 -> 13874837 | I9: =I7+I8 -> 13874837 | J9: =J7+J8 -> 13874837 | K9: =K7+K8 -> 13874837 | ... R9: =R7+R8 -> 13874837 | T9: =SUM(D9:R9) -> 1.9997999e+08 | U9: =T9/T7 -> 0.64389453
B10: Business Overhead | C10: O | D10: {=-SUMPRODUCT((D$39:D$82)*($C$39:$C$82=$C10))} -> -528333.66 | E10: =-SUMPRODUCT((E$39:E$82)*($C$39:$C$82=$C10)) -> -1264703.2 | F10: =-SUMPRODUCT((F$39:F$82)*($C$39:$C$82=$C10)) -> -1264703.2 | G10: =-SUMPRODUCT((G$39:G$82)*($C$39:$C$82=$C10)) -> -1264703.2 | H10: =-SUMPRODUCT((H$39:H$82)*($C$39:$C$82=$C10)) -> -1264703.2 | I10: =-SUMPRODUCT((I$39:I$82)*($C$39:$C$82=$C10)) -> -1264703.2 | J10: =-SUMPRODUCT((J$39:J$82)*($C$39:$C$82=$C10)) -> -1264703.2 | K10: =-SUMPRODUCT((K$39:K$82)*($C$39:$C$82=$C10)) -> -1264703.2 | L10: =-SUMPRODUCT((L$39:L$82)*($C$39:$C$82=$C10)) -> -1264703.2 | ... R10: =-SUMPRODUCT((R$39:R$82)*($C$39:$C$82=$C10)) -> -1264703.2 | T10: =SUM(D10:R10) -> -18234178 | U10: Margin
B11: Profit/Loss Earnings (EBITDA) | D11: =D9+D10 -> 5203939.8 | E11: =E9+E10 -> 12610134 | F11: =F9+F10 -> 12610134 | G11: =G9+G10 -> 12610134 | H11: =H9+H10 -> 12610134 | I11: =I9+I10 -> 12610134 | J11: =J9+J10 -> 12610134 | K11: =K9+K10 -> 12610134 | ... R11: =R9+R10 -> 12610134 | T11: =SUM(D11:R11) -> 1.8174581e+08
B13: Working Capital % per Rev | C13: =Assumptions!D6 -> 0.15 | D13: =D7*$C13 -> 1342115.8 | E13: =E7*$C13 -> 3231764.6 | F13: =F7*$C13 -> 3231764.6 | G13: =G7*$C13 -> 3231764.6 | H13: =H7*$C13 -> 3231764.6 | I13: =I7*$C13 -> 3231764.6 | J13: =J7*$C13 -> 3231764.6 | K13: =K7*$C13 -> 3231764.6 | ... R13: =R7*$C13 -> 3231764.6
B14: Tax Rate (tbd for region) | D14: =WACC!C18 -> 0.21 | E14: =D14 -> 0.21 | F14: =E14 -> 0.21 | G14: =F14 -> 0.21 | H14: =G14 -> 0.21 | I14: =H14 -> 0.21 | J14: =I14 -> 0.21 | K14: =J14 -> 0.21 | L14: =K14 -> 0.21 | ... R14: =Q14 -> 0.21
B15: After Tax Profit/Loss | D15: =IF(D11<0,D11,D11*(1-D14)) -> 4111112.4 | E15: =IF(E11<0,E11,E11*(1-E14)) -> 9962005.6 | F15: =IF(F11<0,F11,F11*(1-F14)) -> 9962005.6 | G15: =IF(G11<0,G11,G11*(1-G14)) -> 9962005.6 | H15: =IF(H11<0,H11,H11*(1-H14)) -> 9962005.6 | I15: =IF(I11<0,I11,I11*(1-I14)) -> 9962005.6 | J15: =IF(J11<0,J11,J11*(1-J14)) -> 9962005.6 | K15: =IF(K11<0,K11,K11*(1-K14)) -> 9962005.6 | ... R15: =IF(R11<0,R11,R11*(1-R14)) -> 9962005.6 | T15: =SUM(D15:R15) -> 1.4357919e+08
B17: Capital Costs | C17: CAP | D17: {=-SUMPRODUCT((D$39:D$82)*($C$39:$C$82=$C17))} -> -15843457 | E17: =-SUMPRODUCT((E$39:E$82)*($C$39:$C$82=$C17)) -> 0 | F17: =-SUMPRODUCT((F$39:F$82)*($C$39:$C$82=$C17)) -> 0 | G17: =-SUMPRODUCT((G$39:G$82)*($C$39:$C$82=$C17)) -> 0 | H17: =-SUMPRODUCT((H$39:H$82)*($C$39:$C$82=$C17)) -> 0 | I17: =-SUMPRODUCT((I$39:I$82)*($C$39:$C$82=$C17)) -> 0 | J17: =-SUMPRODUCT((J$39:J$82)*($C$39:$C$82=$C17)) -> 0 | K17: =-SUMPRODUCT((K$39:K$82)*($C$39:$C$82=$C17)) -> 0 | L17: =-SUMPRODUCT((L$39:L$82)*($C$39:$C$82=$C17)) -> 0 | ... R17: =-SUMPRODUCT((R$39:R$82)*($C$39:$C$82=$C17)) -> 0 | T17: =SUM(D17:R17) -> -15843457
B18: Depreciation | C18: DEP | D18: {=SUMPRODUCT((D$39:D$59)*($C$39:$C$59=$C18))} -> 18743.479 | E18: {=SUMPRODUCT((E$39:E$59)*($C$39:$C$59=$C18))} -> 1056230.4 | F18: {=SUMPRODUCT((F$39:F$59)*($C$39:$C$59=$C18))} -> 1056230.4 | G18: {=SUMPRODUCT((G$39:G$59)*($C$39:$C$59=$C18))} -> 1056230.4 | H18: {=SUMPRODUCT((H$39:H$59)*($C$39:$C$59=$C18))} -> 1056230.4 | I18: {=SUMPRODUCT((I$39:I$59)*($C$39:$C$59=$C18))} -> 1056230.4 | J18: {=SUMPRODUCT((J$39:J$59)*($C$39:$C$59=$C18))} -> 1056230.4 | K18: {=SUMPRODUCT((K$39:K$59)*($C$39:$C$59=$C18))} -> 1056230.4 | ... R18: {=SUMPRODUCT((R$39:R$59)*($C$39:$C$59=$C18))} -> 1056230.4 | T18: =SUM(D18:R18) -> 14805970
B19: Change in Working Capital | D19: =-D13 -> -1342115.8 | E19: =D13-E13 -> -1889648.8 | F19: =E13-F13 -> 0 | G19: =F13-G13 -> 0 | H19: =G13-H13 -> 0 | I19: =H13-I13 -> 0 | J19: =I13-J13 -> 0 | K19: =J13-K13 -> 0 | L19: =K13-L13 -> 0 | ... R19: =Q13-R13 -> 0
B20: Investment | D20: =Proforma!E10 -> 15000000
B21: Free Cash Flow | D21: =SUM(D15:D19) -> -13055716 | E21: =SUM(E15:E19) -> 9128587.3 | F21: =SUM(F15:F19) -> 11018236 | G21: =SUM(G15:G19) -> 11018236 | H21: =SUM(H15:H19) -> 11018236 | I21: =SUM(I15:I19) -> 11018236 | J21: =SUM(J15:J19) -> 11018236 | K21: =SUM(K15:K19) -> 11018236 | ... R21: =SUM(R15:R19) -> 11018236 | T21: =SUM(D21:R21) -> 1.3930994e+08
B23: Discount Rate (WACC) | D23: =WACC!C23 -> 0.2 | E23: =D23 -> 0.2 | F23: =E23 -> 0.2 | G23: =F23 -> 0.2 | H23: =G23 -> 0.2 | I23: =H23 -> 0.2 | J23: =I23 -> 0.2 | K23: =J23 -> 0.2 | L23: =K23 -> 0.2 | ... R23: =Q23 -> 0.2
B24: Discounted Cash Flow | D24: =D21/(1+D23)^D6 -> -10879764 | E24: =E21/(1+E23)^E6 -> 6339296.7 | F24: =F21/(1+F23)^F6 -> 6376294 | G24: =G21/(1+G23)^G6 -> 5313578.3 | H24: =H21/(1+H23)^H6 -> 4427982 | I24: =I21/(1+I23)^I6 -> 3689985 | J24: =J21/(1+J23)^J6 -> 3074987.5 | K24: =K21/(1+K23)^K6 -> 2562489.6 | ... R24: =R21/(1+R23)^R6 -> 715143.81
B25: Multiple on earnings (3yr avg) | C25: 5 | F25: =AVERAGE(D11:F11)*$C25 -> 50707012 | G25: =AVERAGE(E11:G11)*$C25 -> 63050668 | H25: =AVERAGE(F11:H11)*$C25 -> 63050668 | I25: =AVERAGE(G11:I11)*$C25 -> 63050668 | J25: =AVERAGE(H11:J11)*$C25 -> 63050668 | K25: =AVERAGE(I11:K11)*$C25 -> 63050668 | L25: =AVERAGE(J11:L11)*$C25 -> 63050668 | M25: =AVERAGE(K11:M11)*$C25 -> 63050668 | ... R25: =AVERAGE(P11:R11)*$C25 -> 63050668
B27: Fixed Assets | D27: =SUM($D44:D44)-SUM($D46:D46) -> 15824713 | E27: =SUM($D44:E44)-SUM($D46:E46) -> 14768483 | F27: =SUM($D44:F44)-SUM($D46:F46) -> 13712252 | G27: =SUM($D44:G44)-SUM($D46:G46) -> 12656022 | H27: =SUM($D44:H44)-SUM($D46:H46) -> 11599791 | I27: =SUM($D44:I44)-SUM($D46:I46) -> 10543561 | J27: =SUM($D44:J44)-SUM($D46:J46) -> 9487330.5 | K27: =SUM($D44:K44)-SUM($D46:K46) -> 8431100 | ... R27: =SUM($D44:R44)-SUM($D46:R46) -> 1037487
B28: Investment | D28: =D20 -> 15000000 | E28: =E20 -> 0 | F28: =F20 -> 0 | G28: =G20 -> 0 | H28: =H20 -> 0 | I28: =I20 -> 0 | J28: =J20 -> 0 | K28: =K20 -> 0 | ... R28: =R20 -> 0
B29: Project NPV | H29: =NPV(0.1,D24:H24) -> 6517671.9 | R29: =NPV(0.1,D24:R24) -> 14574636
B30: Project IRR | G30: Project IRR | H30: =IRR(D21:H21,0.1) -> 0.67926385 | Q30: Project IRR | R30: =IRR(D21:R21,0.1) -> 0.78024157
B32: Series A Investor Equity | D32: =IF(ModelDescription!$D$23="On", IF(ROUNDUP((AVERAGE(Assumptions!$B$82:$B$88)+Assumptions!$D$33)/12, 0)>Economics!D$6, Assumptions!$D$25, Assumptions!$D$30), Assumptions!$D$25) -> 0.5 | E32: =IF(ModelDescription!$D$23=Assumptions!$E$28, IF(ROUNDUP((AVERAGE(Assumptions!$B$82:$B$88)+Assumptions!$D$33)/12, 0)>Economics!E$6, Assumptions!$D$25, Assumptions!$D$30), Assumptions!$D$25) -> 0.5 | F32: =IF(ModelDescription!$D$23=Assumptions!$E$28, IF(ROUNDUP((AVERAGE(Assumptions!$B$82:$B$88)+Assumptions!$D$33)/12, 0)>Economics!F$6, Assumptions!$D$25, Assumptions!$D$30), Assumptions!$D$25) -> 0.5 | G32: =IF(ModelDescription!$D$23=Assumptions!$E$28, IF(ROUNDUP((AVERAGE(Assumptions!$B$82:$B$88)+Assumptions!$D$33)/12, 0)>Economics!G$6, Assumptions!$D$25, Assumptions!$D$30), Assumptions!$D$25) -> 0.5 | H32: =IF(ModelDescription!$D$23=Assumptions!$E$28, IF(ROUNDUP((AVERAGE(Assumptions!$B$82:$B$88)+Assumptions!$D$33)/12, 0)>Economics!H$6, Assumptions!$D$25, Assumptions!$D$30), Assumptions!$D$25) -> 0.5 | I32: =IF(ModelDescription!$D$23=Assumptions!$E$28, IF(ROUNDUP((AVERAGE(Assumptions!$B$82:$B$88)+Assumptions!$D$33)/12, 0)>Economics!I$6, Assumptions!$D$25, Assumptions!$D$30), Assumptions!$D$25) -> 0.5 | J32: =IF(ModelDescription!$D$23=Assumptions!$E$28, IF(ROUNDUP((AVERAGE(Assumptions!$B$82:$B$88)+Assumptions!$D$33)/12, 0)>Economics!J$6, Assumptions!$D$25, Assumptions!$D$30), Assumptions!$D$25) -> 0.5 | K32: =IF(ModelDescription!$D$23=Assumptions!$E$28, IF(ROUNDUP((AVERAGE(Assumptions!$B$82:$B$88)+Assumptions!$D$33)/12, 0)>Economics!K$6, Assumptions!$D$25, Assumptions!$D$30), Assumptions!$D$25) -> 0.5 | L32: =IF(ModelDescription!$D$23=Assumptions!$E$28, IF(ROUNDUP((AVERAGE(Assumptions!$B$82:$B$88)+Assumptions!$D$33)/12, 0)>Economics!L$6, Assumptions!$D$25, Assumptions!$D$30), Assumptions!$D$25) -> 0.5 | ... R32: =IF(ModelDescription!$D$23=Assumptions!$E$28, IF(ROUNDUP((AVERAGE(Assumptions!$B$82:$B$88)+Assumptions!$D$33)/12, 0)>Economics!R$6, Assumptions!$D$25, Assumptions!$D$30), Assumptions!$D$25) -> 0.5
B33: Series A Investor Cash Flow | D33: =D$32*(D15+D18+D19)-Proforma!$F$26 -> -13606130 | E33: =E$32*(E15+E18+E19) -> 4564293.6 | F33: =F$32*(F15+F18+F19) -> 5509118 | G33: =G$32*(G15+G18+G19) -> 5509118 | H33: =H$32*(H15+H18+H19) -> 5509118 | I33: =I$32*(I15+I18+I19) -> 5509118 | J33: =J$32*(J15+J18+J19) -> 5509118 | K33: =K$32*(K15+K18+K19) -> 5509118 | L33: =L$32*(L15+L18+L19) -> 5509118 | ... R33: =R$32*(R15+R18+R19) -> 5509118
B34: Series A Investor IRR | G34: IRR | H34: =IRR(D33:H33) -> 0.19504061 | Q34: IRR | R34: =IRR(D33:R33) -> 0.38133255
B36: NOPAT | D36: =(D40-D42-D43-D46)*(1-D14) -> 4096305.1 | E36: =(E40-E42-E43-E46)*(1-E14) -> 9127583.6 | F36: =(F40-F42-F43-F46)*(1-F14) -> 9127583.6 | G36: =(G40-G42-G43-G46)*(1-G14) -> 9127583.6 | H36: =(H40-H42-H43-H46)*(1-H14) -> 9127583.6 | I36: =(I40-I42-I43-I46)*(1-I14) -> 9127583.6 | J36: =(J40-J42-J43-J46)*(1-J14) -> 9127583.6 | K36: =(K40-K42-K43-K46)*(1-K14) -> 9127583.6 | ... R36: =(R40-R42-R43-R46)*(1-R14) -> 9127583.6
B37: ROIC | D37: =SUM($D36:D36)/SUM($D41:D41) -> 0.273087 | E37: =SUM($D36:E36)/SUM($D41:E41) -> 0.88159258 | F37: =SUM($D36:F36)/SUM($D41:F41) -> 1.4900981 | G37: =SUM($D36:G36)/SUM($D41:G41) -> 2.0986037 | H37: =SUM($D36:H36)/SUM($D41:H41) -> 2.7071093 | I37: =SUM($D36:I36)/SUM($D41:I41) -> 3.3156149 | J37: =SUM($D36:J36)/SUM($D41:J41) -> 3.9241204 | K37: =SUM($D36:K36)/SUM($D41:K41) -> 4.532626 | ... R37: =SUM($D36:R36)/SUM($D41:R41) -> 8.792165
A39: Summary Info
B40: Revenue | C40: R | D40: =SUM(MthCashSum!F9:Q9) -> 8947438.7 | E40: =SUM(MthCashSum!R9:AC9) -> 21545097 | F40: =SUM(MthCashSum!AD9:AO9) -> 21545097 | G40: =SUM(MthCashSum!AP9:BA9) -> 21545097 | H40: =SUM(MthCashSum!BB9:BM9) -> 21545097 | I40: =SUM(MthCashSum!BN9:BY9) -> 21545097 | J40: =SUM(MthCashSum!BZ9:CK9) -> 21545097 | K40: =SUM(MthCashSum!CL9:CW9) -> 21545097 | L40: =SUM(MthCashSum!CX9:DI9) -> 21545097 | M40: =SUM(MthCashSum!DJ9:DU9) -> 21545097 | N40: =SUM(MthCashSum!DV9:EG9) -> 21545097 | O40: =SUM(MthCashSum!EH9:ES9) -> 21545097 | P40: =SUM(MthCashSum!ET9:FE9) -> 21545097 | Q40: =SUM(MthCashSum!FF9:FQ9) -> 21545097 | R40: =SUM(MthCashSum!FR9:GC9) -> 21545097 | T40: =SUM(D40:R40) -> 3.105788e+08
B41: Investment | C41: L | D41: =SUM(MthCashSum!F10:Q10) -> 15000000 | E41: =SUM(MthCashSum!R10:AC10) -> 0 | F41: =SUM(MthCashSum!AD10:AO10) -> 0 | G41: =SUM(MthCashSum!AP10:BA10) -> 0 | H41: =SUM(MthCashSum!BB10:BM10) -> 0 | I41: =SUM(MthCashSum!BN10:BY10) -> 0 | J41: =SUM(MthCashSum!BZ10:CK10) -> 0 | K41: =SUM(MthCashSum!CL10:CW10) -> 0 | L41: =SUM(MthCashSum!CX10:DI10) -> 0 | M41: =SUM(MthCashSum!DJ10:DU10) -> 0 | N41: =SUM(MthCashSum!DV10:EG10) -> 0 | O41: =SUM(MthCashSum!EH10:ES10) -> 0 | P41: =SUM(MthCashSum!ET10:FE10) -> 0 | Q41: =SUM(MthCashSum!FF10:FQ10) -> 0 | R41: =SUM(MthCashSum!FR10:GC10) -> 0 | T41: =SUM(D41:R41) -> 15000000
B42: Costs | C42: C | D42: =SUM(MthCashSum!F11:Q11) -> 3215165.3 | E42: =SUM(MthCashSum!R11:AC11) -> 7670260.4 | F42: =SUM(MthCashSum!AD11:AO11) -> 7670260.4 | G42: =SUM(MthCashSum!AP11:BA11) -> 7670260.4 | H42: =SUM(MthCashSum!BB11:BM11) -> 7670260.4 | I42: =SUM(MthCashSum!BN11:BY11) -> 7670260.4 | J42: =SUM(MthCashSum!BZ11:CK11) -> 7670260.4 | K42: =SUM(MthCashSum!CL11:CW11) -> 7670260.4 | L42: =SUM(MthCashSum!CX11:DI11) -> 7670260.4 | M42: =SUM(MthCashSum!DJ11:DU11) -> 7670260.4 | N42: =SUM(MthCashSum!DV11:EG11) -> 7670260.4 | O42: =SUM(MthCashSum!EH11:ES11) -> 7670260.4 | P42: =SUM(MthCashSum!ET11:FE11) -> 7670260.4 | Q42: =SUM(MthCashSum!FF11:FQ11) -> 7670260.4 | R42: =SUM(MthCashSum!FR11:GC11) -> 7670260.4 | T42: =SUM(D42:R42) -> 1.1059881e+08
B43: Business Overhead | C43: O | D43: =SUM(MthCashSum!F12:Q12) -> 528333.66 | E43: =SUM(MthCashSum!R12:AC12) -> 1264703.2 | F43: =SUM(MthCashSum!AD12:AO12) -> 1264703.2 | G43: =SUM(MthCashSum!AP12:BA12) -> 1264703.2 | H43: =SUM(MthCashSum!BB12:BM12) -> 1264703.2 | I43: =SUM(MthCashSum!BN12:BY12) -> 1264703.2 | J43: =SUM(MthCashSum!BZ12:CK12) -> 1264703.2 | K43: =SUM(MthCashSum!CL12:CW12) -> 1264703.2 | L43: =SUM(MthCashSum!CX12:DI12) -> 1264703.2 | M43: =SUM(MthCashSum!DJ12:DU12) -> 1264703.2 | N43: =SUM(MthCashSum!DV12:EG12) -> 1264703.2 | O43: =SUM(MthCashSum!EH12:ES12) -> 1264703.2 | P43: =SUM(MthCashSum!ET12:FE12) -> 1264703.2 | Q43: =SUM(MthCashSum!FF12:FQ12) -> 1264703.2 | R43: =SUM(MthCashSum!FR12:GC12) -> 1264703.2 | T43: =SUM(D43:R43) -> 18234178
B44: Capital Costs | C44: CAP | D44: =SUM(MthCashSum!F13:Q13) -> 15843457 | E44: =SUM(MthCashSum!R13:AC13) -> 0 | F44: =SUM(MthCashSum!AD13:AO13) -> 0 | G44: =SUM(MthCashSum!AP13:BA13) -> 0 | H44: =SUM(MthCashSum!BB13:BM13) -> 0 | I44: =SUM(MthCashSum!BN13:BY13) -> 0 | J44: =SUM(MthCashSum!BZ13:CK13) -> 0 | K44: =SUM(MthCashSum!CL13:CW13) -> 0 | L44: =SUM(MthCashSum!CX13:DI13) -> 0 | M44: =SUM(MthCashSum!DJ13:DU13) -> 0 | N44: =SUM(MthCashSum!DV13:EG13) -> 0 | O44: =SUM(MthCashSum!EH13:ES13) -> 0 | P44: =SUM(MthCashSum!ET13:FE13) -> 0 | Q44: =SUM(MthCashSum!FF13:FQ13) -> 0 | R44: =SUM(MthCashSum!FR13:GC13) -> 0 | T44: =SUM(D44:R44) -> 15843457
B45: Loan Payment | C45: C | D45: =SUM(MthCashSum!F14:Q14) -> 0 | E45: =SUM(MthCashSum!R14:AC14) -> 0 | F45: =SUM(MthCashSum!AD14:AO14) -> 0 | G45: =SUM(MthCashSum!AP14:BA14) -> 0 | H45: =SUM(MthCashSum!BB14:BM14) -> 0 | I45: =SUM(MthCashSum!BN14:BY14) -> 0 | J45: =SUM(MthCashSum!BZ14:CK14) -> 0 | K45: =SUM(MthCashSum!CL14:CW14) -> 0 | L45: =SUM(MthCashSum!CX14:DI14) -> 0 | M45: =SUM(MthCashSum!DJ14:DU14) -> 0 | N45: =SUM(MthCashSum!DV14:EG14) -> 0 | O45: =SUM(MthCashSum!EH14:ES14) -> 0 | P45: =SUM(MthCashSum!ET14:FE14) -> 0 | Q45: =SUM(MthCashSum!FF14:FQ14) -> 0 | R45: =SUM(MthCashSum!FR14:GC14) -> 0 | T45: =SUM(D45:R45) -> 0
B46: Depreciation | C46: DEP | D46: =SUM(MthCashSum!F15:Q15) -> 18743.479 | E46: =SUM(MthCashSum!R15:AC15) -> 1056230.4 | F46: =SUM(MthCashSum!AD15:AO15) -> 1056230.4 | G46: =SUM(MthCashSum!AP15:BA15) -> 1056230.4 | H46: =SUM(MthCashSum!BB15:BM15) -> 1056230.4 | I46: =SUM(MthCashSum!BN15:BY15) -> 1056230.4 | J46: =SUM(MthCashSum!BZ15:CK15) -> 1056230.4 | K46: =SUM(MthCashSum!CL15:CW15) -> 1056230.4 | L46: =SUM(MthCashSum!CX15:DI15) -> 1056230.4 | M46: =SUM(MthCashSum!DJ15:DU15) -> 1056230.4 | N46: =SUM(MthCashSum!DV15:EG15) -> 1056230.4 | O46: =SUM(MthCashSum!EH15:ES15) -> 1056230.4 | P46: =SUM(MthCashSum!ET15:FE15) -> 1056230.4 | Q46: =SUM(MthCashSum!FF15:FQ15) -> 1056230.4 | R46: =SUM(MthCashSum!FR15:GC15) -> 1056230.4 | T46: =SUM(D46:R46) -> 14805970
A48: Production Info
B49: Equivalent tires processed | D49: =SUM(Proforma!F133:Q133) -> 685440 | E49: =SUM(Proforma!R133:AC133) -> 1635200 | F49: =SUM(Proforma!AD133:AO133) -> 1635200 | G49: =SUM(Proforma!AP133:BA133) -> 1635200 | H49: =SUM(Proforma!BB133:BM133) -> 1635200 | I49: =SUM(Proforma!BN133:BY133) -> 1635200 | J49: =SUM(Proforma!BZ133:CK133) -> 1635200 | K49: =SUM(Proforma!CL133:CW133) -> 1635200 | L49: =SUM(Proforma!CX133:DI133) -> 1635200 | M49: =SUM(Proforma!DJ133:DU133) -> 1635200 | N49: =SUM(Proforma!DV133:EG133) -> 1635200 | O49: =SUM(Proforma!EH133:ES133) -> 1635200 | P49: =SUM(Proforma!ET133:FE133) -> 1635200 | Q49: =SUM(Proforma!FF133:FQ133) -> 1635200 | R49: =SUM(Proforma!FR133:GC133) -> 1635200 | T49: =SUM(D49:R49) -> 23578240
B50: Solvent (gallons) | D50: =SUM(Proforma!F144:Q144) -> 740275.2 | E50: =SUM(Proforma!R144:AC144) -> 1766016 | F50: =SUM(Proforma!AD144:AO144) -> 1766016 | G50: =SUM(Proforma!AP144:BA144) -> 1766016 | H50: =SUM(Proforma!BB144:BM144) -> 1766016 | I50: =SUM(Proforma!BN144:BY144) -> 1766016 | J50: =SUM(Proforma!BZ144:CK144) -> 1766016 | K50: =SUM(Proforma!CL144:CW144) -> 1766016 | L50: =SUM(Proforma!CX144:DI144) -> 1766016 | M50: =SUM(Proforma!DJ144:DU144) -> 1766016 | N50: =SUM(Proforma!DV144:EG144) -> 1766016 | O50: =SUM(Proforma!EH144:ES144) -> 1766016 | P50: =SUM(Proforma!ET144:FE144) -> 1766016 | Q50: =SUM(Proforma!FF144:FQ144) -> 1766016 | R50: =SUM(Proforma!FR144:GC144) -> 1766016 | T50: =SUM(D50:R50) -> 25464499
...

Sheet Proforma
A2: =ModelDescription!A2 -> Economic Forecasting Model
A3: =ModelDescription!C4 -> Noble, OK 6 Processor Facility - Series A + Series B
B5: Period | F5: =Assumptions!D76 -> 1 | G5: =Assumptions!E76 -> 2 | H5: =Assumptions!F76 -> 3 | I5: =Assumptions!G76 -> 4 | J5: =Assumptions!H76 -> 5 | K5: =Assumptions!I76 -> 6 | L5: =Assumptions!J76 -> 7 | M5: =Assumptions!K76 -> 8 | ... GC5: =Assumptions!GA76 -> 180
B6: Year | F6: =Assumptions!D77 -> 2026 | G6: =Assumptions!E77 -> 2026 | H6: =Assumptions!F77 -> 2026 | I6: =Assumptions!G77 -> 2026 | J6: =Assumptions!H77 -> 2026 | K6: =Assumptions!I77 -> 2026 | L6: =Assumptions!J77 -> 2026 | M6: =Assumptions!K77 -> 2026 | ... GC6: =Assumptions!GA77 -> 2040
B7: Month | F7: =Assumptions!D78 -> Jan | G7: =Assumptions!E78 -> Feb | H7: =Assumptions!F78 -> Mar | I7: =Assumptions!G78 -> Apr | J7: =Assumptions!H78 -> May | K7: =Assumptions!I78 -> Jun | L7: =Assumptions!J78 -> Jul | M7: =Assumptions!K78 -> Aug | ... GC7: =Assumptions!GA78 -> Dec
B8: Days | F8: =Assumptions!D80 -> 31 | G8: =Assumptions!E80 -> 28 | H8: =Assumptions!F80 -> 31 | I8: =Assumptions!G80 -> 30 | J8: =Assumptions!H80 -> 31 | K8: =Assumptions!I80 -> 30 | L8: =Assumptions!J80 -> 31 | M8: =Assumptions!K80 -> 31 | ... GC8: =Assumptions!GA80 -> 31
B9: Revenue | C9: R | E9: =SUM(F9:GC9) -> 3.105788e+08 | F9: {=SUMPRODUCT((F$25:F$162)*($C$25:$C$162=$C9))} -> 0 | G9: {=SUMPRODUCT((G$25:G$162)*($C$25:$C$162=$C9))} -> 0 | H9: {=SUMPRODUCT((H$25:H$162)*($C$25:$C$162=$C9))} -> 0 | I9: {=SUMPRODUCT((I$25:I$162)*($C$25:$C$162=$C9))} -> 0 | J9: {=SUMPRODUCT((J$25:J$162)*($C$25:$C$162=$C9))} -> 0 | K9: {=SUMPRODUCT((K$25:K$162)*($C$25:$C$162=$C9))} -> 0 | L9: {=SUMPRODUCT((L$25:L$162)*($C$25:$C$162=$C9))} -> 0 | M9: {=SUMPRODUCT((M$25:M$162)*($C$25:$C$162=$C9))} -> 1762387.2 | ... GC9: {=SUMPRODUCT((GC$25:GC$162)*($C$25:$C$162=$C9))} -> 1829857.6
B10: Capital Investment ( Loan) | C10: L | E10: =SUM(F10:GC10) -> 15000000 | F10: {=SUMPRODUCT((F$25:F$162)*($C$25:$C$162=$C10))} -> 15000000 | G10: {=SUMPRODUCT((G$25:G$162)*($C$25:$C$162=$C10))} -> 0 | H10: {=SUMPRODUCT((H$25:H$162)*($C$25:$C$162=$C10))} -> 0 | I10: {=SUMPRODUCT((I$25:I$162)*($C$25:$C$162=$C10))} -> 0 | J10: {=SUMPRODUCT((J$25:J$162)*($C$25:$C$162=$C10))} -> 0 | K10: {=SUMPRODUCT((K$25:K$162)*($C$25:$C$162=$C10))} -> 0 | L10: {=SUMPRODUCT((L$25:L$162)*($C$25:$C$162=$C10))} -> 0 | M10: {=SUMPRODUCT((M$25:M$162)*($C$25:$C$162=$C10))} -> 0 | ... GC10: {=SUMPRODUCT((GC$25:GC$162)*($C$25:$C$162=$C10))} -> 0
B11: Costs | C11: C | E11: =SUM(F11:GC11) -> 1.1059881e+08 | F11: {=SUMPRODUCT((F$25:F$162)*($C$25:$C$162=$C11))} -> 0 | G11: {=SUMPRODUCT((G$25:G$162)*($C$25:$C$162=$C11))} -> 0 | H11: {=SUMPRODUCT((H$25:H$162)*($C$25:$C$162=$C11))} -> 0 | I11: {=SUMPRODUCT((I$25:I$162)*($C$25:$C$162=$C11))} -> 0 | J11: {=SUMPRODUCT((J$25:J$162)*($C$25:$C$162=$C11))} -> 0 | K11: {=SUMPRODUCT((K$25:K$162)*($C$25:$C$162=$C11))} -> 0 | L11: {=SUMPRODUCT((L$25:L$162)*($C$25:$C$162=$C11))} -> 0 | M11: {=SUMPRODUCT((M$25:M$162)*($C$25:$C$162=$C11))} -> 651421.46 | ... GC11: {=SUMPRODUCT((GC$25:GC$162)*($C$25:$C$162=$C11))} -> 651421.46
B12: Business Overhead | C12: O | E12: =SUM(F12:GC12) -> 18234178 | F12: {=SUMPRODUCT((F$25:F$162)*($C$25:$C$162=$C12))} -> 0 | G12: {=SUMPRODUCT((G$25:G$162)*($C$25:$C$162=$C12))} -> 0 | H12: {=SUMPRODUCT((H$25:H$162)*($C$25:$C$162=$C12))} -> 0 | I12: {=SUMPRODUCT((I$25:I$162)*($C$25:$C$162=$C12))} -> 0 | J12: {=SUMPRODUCT((J$25:J$162)*($C$25:$C$162=$C12))} -> 0 | K12: {=SUMPRODUCT((K$25:K$162)*($C$25:$C$162=$C12))} -> 0 | L12: {=SUMPRODUCT((L$25:L$162)*($C$25:$C$162=$C12))} -> 0 | M12: {=SUMPRODUCT((M$25:M$162)*($C$25:$C$162=$C12))} -> 106266.3 | ... GC12: {=SUMPRODUCT((GC$25:GC$162)*($C$25:$C$162=$C12))} -> 106266.3
B13: Capital Costs | C13: CAP | E13: =SUM(F13:GC13) -> 15843457 | F13: {=SUMPRODUCT((F$25:F$162)*($C$25:$C$162=$C13))} -> 6697158.3 | G13: {=SUMPRODUCT((G$25:G$162)*($C$25:$C$162=$C13))} -> 3337788.9 | H13: {=SUMPRODUCT((H$25:H$162)*($C$25:$C$162=$C13))} -> 3077158.3 | I13: {=SUMPRODUCT((I$25:I$162)*($C$25:$C$162=$C13))} -> 735585.86 | J13: {=SUMPRODUCT((J$25:J$162)*($C$25:$C$162=$C13))} -> 398442.91 | K13: {=SUMPRODUCT((K$25:K$162)*($C$25:$C$162=$C13))} -> 553103.08 | L13: {=SUMPRODUCT((L$25:L$162)*($C$25:$C$162=$C13))} -> 510109.58 | M13: {=SUMPRODUCT((M$25:M$162)*($C$25:$C$162=$C13))} -> 510109.58 | ... GC13: {=SUMPRODUCT((GC$25:GC$162)*($C$25:$C$162=$C13))} -> 0
B14: Loan Payment | C14: LP | E14: =SUM(F14:GC14) -> 0 | F14: {=SUMPRODUCT((F$25:F$162)*($C$25:$C$162=$C14))} -> 0 | G14: {=SUMPRODUCT((G$25:G$162)*($C$25:$C$162=$C14))} -> 0 | H14: {=SUMPRODUCT((H$25:H$162)*($C$25:$C$162=$C14))} -> 0 | I14: {=SUMPRODUCT((I$25:I$162)*($C$25:$C$162=$C14))} -> 0 | J14: {=SUMPRODUCT((J$25:J$162)*($C$25:$C$162=$C14))} -> 0 | K14: {=SUMPRODUCT((K$25:K$162)*($C$25:$C$162=$C14))} -> 0 | L14: {=SUMPRODUCT((L$25:L$162)*($C$25:$C$162=$C14))} -> 0 | M14: {=SUMPRODUCT((M$25:M$162)*($C$25:$C$162=$C14))} -> 0 | ... GC14: {=SUMPRODUCT((GC$25:GC$162)*($C$25:$C$162=$C14))} -> 0
B15: Depreciation | C15: DEP | E15: =SUM(F15:GC15) -> 14805970 | F15: {=SUMPRODUCT((F$25:F$162)*($C$25:$C$162=$C15))} -> 0 | G15: {=SUMPRODUCT((G$25:G$162)*($C$25:$C$162=$C15))} -> 0 | H15: {=SUMPRODUCT((H$25:H$162)*($C$25:$C$162=$C15))} -> 0 | I15: {=SUMPRODUCT((I$25:I$162)*($C$25:$C$162=$C15))} -> 0 | J15: {=SUMPRODUCT((J$25:J$162)*($C$25:$C$162=$C15))} -> 0 | K15: {=SUMPRODUCT((K$25:K$162)*($C$25:$C$162=$C15))} -> 0 | L15: {=SUMPRODUCT((L$25:L$162)*($C$25:$C$162=$C15))} -> 0 | M15: {=SUMPRODUCT((M$25:M$162)*($C$25:$C$162=$C15))} -> 0 | ... GC15: {=SUMPRODUCT((GC$25:GC$162)*($C$25:$C$162=$C15))} -> 88019.203
B16: Monthly Profit/Loss (EBITDA) | F16: =SUM(F9:F10)-SUM(F11:F14) -> 8302841.7 | G16: =SUM(G9:G10)-SUM(G11:G14) -> -3337788.9 | H16: =SUM(H9:H10)-SUM(H11:H14) -> -3077158.3 | I16: =SUM(I9:I10)-SUM(I11:I14) -> -735585.86 | J16: =SUM(J9:J10)-SUM(J11:J14) -> -398442.91 | K16: =SUM(K9:K10)-SUM(K11:K14) -> -553103.08 | L16: =SUM(L9:L10)-SUM(L11:L14) -> -510109.58 | M16: =SUM(M9:M10)-SUM(M11:M14) -> 494589.86 | ... GC16: =SUM(GC9:GC10)-SUM(GC11:GC14) -> 1072169.8
B17: Project Cumulative Cash Flow | F17: =E17+F16 -> 8302841.7 | G17: =F17+G16 -> 4965052.8 | H17: =G17+H16 -> 1887894.4 | I17: =H17+I16 -> 1152308.6 | J17: =I17+J16 -> 753865.66 | K17: =J17+K16 -> 200762.58 | L17: =K17+L16 -> -309347 | M17: =L17+M16 -> 185242.87 | ... GC17: =GB17+GC16 -> 1.8090235e+08
B21: Investment Rounds | F21: =IF(Assumptions!$D$24=Proforma!F5, Assumptions!$B$24, IF(AND(ModelDescription!$D$23=Assumptions!$E$28, Assumptions!$D$29=Proforma!F5), Assumptions!$B$29, "")) -> Series A | G21: =IF(Assumptions!$D$24=Proforma!G5, Assumptions!$B$24, IF(AND(ModelDescription!$D$23=Assumptions!$E$28, Assumptions!$D$29=Proforma!G5), Assumptions!$B$29, "")) | H21: =IF(Assumptions!$D$24=Proforma!H5, Assumptions!$B$24, IF(AND(ModelDescription!$D$23=Assumptions!$E$28, Assumptions!$D$29=Proforma!H5), Assumptions!$B$29, "")) | I21: =IF(Assumptions!$D$24=Proforma!I5, Assumptions!$B$24, IF(AND(ModelDescription!$D$23=Assumptions!$E$28, Assumptions!$D$29=Proforma!I5), Assumptions!$B$29, "")) | J21: =IF(Assumptions!$D$24=Proforma!J5, Assumptions!$B$24, IF(AND(ModelDescription!$D$23=Assumptions!$E$28, Assumptions!$D$29=Proforma!J5), Assumptions!$B$29, "")) | K21: =IF(Assumptions!$D$24=Proforma!K5, Assumptions!$B$24, IF(AND(ModelDescription!$D$23=Assumptions!$E$28, Assumptions!$D$29=Proforma!K5), Assumptions!$B$29, "")) | L21: =IF(Assumptions!$D$24=Proforma!L5, Assumptions!$B$24, IF(AND(ModelDescription!$D$23=Assumptions!$E$28, Assumptions!$D$29=Proforma!L5), Assumptions!$B$29, "")) | M21: =IF(Assumptions!$D$24=Proforma!M5, Assumptions!$B$24, IF(AND(ModelDescription!$D$23=Assumptions!$E$28, Assumptions!$D$29=Proforma!M5), Assumptions!$B$29, "")) | ... GC21: =IF(Assumptions!$D$24=Proforma!GC5, Assumptions!$B$24, IF(AND(ModelDescription!$D$23=Assumptions!$E$28, Assumptions!$D$29=Proforma!GC5), Assumptions!$B$29, ""))
B22: Plants Beginning Construction | F22: =COUNTIF(Assumptions!D81:D88, 1) -> 1 | G22: =COUNTIF(Assumptions!E81:E88, 1) -> 0 | H22: =COUNTIF(Assumptions!F81:F88, 1) -> 0 | I22: =COUNTIF(Assumptions!G81:G88, 1) -> 0 | J22: =COUNTIF(Assumptions!H81:H88, 1) -> 0 | K22: =COUNTIF(Assumptions!I81:I88, 1) -> 0 | L22: =COUNTIF(Assumptions!J81:J88, 1) -> 0 | M22: =COUNTIF(Assumptions!K81:K88, 1) -> 0 | ... GC22: =COUNTIF(Assumptions!GA81:GA88, 1) -> 0
B23: Number of Plants in Operation | F23: =E23+COUNTIF(Assumptions!D81:D88, Assumptions!$D$33) -> 0 | G23: =F23+COUNTIF(Assumptions!E81:E88, Assumptions!$D$33) -> 0 | H23: =G23+COUNTIF(Assumptions!F81:F88, Assumptions!$D$33) -> 0 | I23: =H23+COUNTIF(Assumptions!G81:G88, Assumptions!$D$33) -> 0 | J23: =I23+COUNTIF(Assumptions!H81:H88, Assumptions!$D$33) -> 0 | K23: =J23+COUNTIF(Assumptions!I81:I88, Assumptions!$D$33) -> 0 | L23: =K23+COUNTIF(Assumptions!J81:J88, Assumptions!$D$33) -> 0 | M23: =L23+COUNTIF(Assumptions!K81:K88, Assumptions!$D$33) -> 1 | ... GC23: =GB23+COUNTIF(Assumptions!GA81:GA88, Assumptions!$D$33) -> 1
A25: Project Capital
B26: Capital Investment USD | C26: L | E26: =SUM(F26:GC26) -> 15000000 | F26: =IF(F21="Series A", Assumptions!$D$23, IF(F21="Series B", Assumptions!$D$28, 0)) -> 15000000 | G26: =IF(G21="Series A", Assumptions!$D$23, IF(G21="Series B", Assumptions!$D$28, 0)) -> 0 | H26: =IF(H21="Series A", Assumptions!$D$23, IF(H21="Series B", Assumptions!$D$28, 0)) -> 0 | I26: =IF(I21="Series A", Assumptions!$D$23, IF(I21="Series B", Assumptions!$D$28, 0)) -> 0 | J26: =IF(J21="Series A", Assumptions!$D$23, IF(J21="Series B", Assumptions!$D$28, 0)) -> 0 | K26: =IF(K21="Series A", Assumptions!$D$23, IF(K21="Series B", Assumptions!$D$28, 0)) -> 0 | L26: =IF(L21="Series A", Assumptions!$D$23, IF(L21="Series B", Assumptions!$D$28, 0)) -> 0 | M26: =IF(M21="Series A", Assumptions!$D$23, IF(M21="Series B", Assumptions!$D$28, 0)) -> 0 | ... GC26: =IF(GC21="Series A", Assumptions!$D$23, IF(GC21="Series B", Assumptions!$D$28, 0)) -> 0
A28: Total Capital Costs
B30: Equipment & Materials | E30: =SUM(F30:GC30) -> 7290598 | F30: =SUM(_xlfn.IFNA(_xlfn.XLOOKUP(Assumptions!D$81, '1 Machine Build'!$F$11:$Q$11, '1 Machine Build'!$F12:$Q12), 0), _xlfn.IFNA(_xlfn.XLOOKUP(Assumptions!D$82, '1 Machine Build'!$F$11:$Q$11, '1 Machine Build'!$F12:$Q12), 0), _xlfn.IFNA(_xlfn.XLOOKUP(Assumptions!D$83, '1 Machine Build'!$F$11:$Q$11, '1 Machine Build'!$F12:$Q12), 0), _xlfn.IFNA(_xlfn.XLOOKUP(Assumptions!D$84, '1 Machine Build'!$F$11:$Q$11, '1 Machine Build'!$F12:$Q12), 0), _xlfn.IFNA(_xlfn.XLOOKUP(Assumptions!D$85, '1 Machine Build'!$F$11:$Q$11, '1 Machine Build'!$F12:$Q12), 0), _xlfn.IFNA(_xlfn.XLOOKUP(Assumptions!D$86, '1 Machine Build'!$F$11:$Q$11, '1 Machine Build'!$F12:$Q12), 0), _xlfn.IFNA(_xlfn.XLOOKUP(Assumptions!D$87, '1 Machine Build'!$F$11:$Q$11, '1 Machine Build'!$F12:$Q12), 0), _xlfn.IFNA(_xlfn.XLOOKUP(Assumptions!D$88, '1 Machine Build'!$F$11:$Q$11, '1 Machine Build'!$F12:$Q12), 0)) -> 4200199.3 | G30: =SUM(_xlfn.IFNA(_xlfn.XLOOKUP(Assumptions!E$81, '1 Machine Build'!$F$11:$Q$11, '1 Machine Build'!$F12:$Q12), 0), _xlfn.IFNA(_xlfn.XLOOKUP(Assumptions!E$82, '1 Machine Build'!$F$11:$Q$11, '1 Machine Build'!$F12:$Q12), 0), _xlfn.IFNA(_xlfn.XLOOKUP(Assumptions!E$83, '1 Machine Build'!$F$11:$Q$11, '1 Machine Build'!$F12:$Q12), 0), _xlfn.IFNA(_xlfn.XLOOKUP(Assumptions!E$84, '1 Machine Build'!$F$11:$Q$11, '1 Machine Build'!$F12:$Q12), 0), _xlfn.IFNA(_xlfn.XLOOKUP(Assumptions!E$85, '1 Machine Build'!$F$11:$Q$11, '1 Machine Build'!$F12:$Q12), 0), _xlfn.IFNA(_xlfn.XLOOKUP(Assumptions!E$86, '1 Machine Build'!$F$11:$Q$11, '1 Machine Build'!$F12:$Q12), 0), _xlfn.IFNA(_xlfn.XLOOKUP(Assumptions!E$87, '1 Machine Build'!$F$11:$Q$11, '1 Machine Build'!$F12:$Q12), 0), _xlfn.IFNA(_xlfn.XLOOKUP(Assumptions!E$88, '1 Machine Build'!$F$11:$Q$11, '1 Machine Build'!$F12:$Q12), 0)) -> 1698949.3 | H30: =SUM(_xlfn.IFNA(_xlfn.XLOOKUP(Assumptions!F$81, '1 Machine Build'!$F$11:$Q$11, '1 Machine Build'!$F12:$Q12), 0), _xlfn.IFNA(_xlfn.XLOOKUP(Assumptions!F$82, '1 Machine Build'!$F$11:$Q$11, '1 Machine Build'!$F12:$Q12), 0), _xlfn.IFNA(_xlfn.XLOOKUP(Assumptions!F$83, '1 Machine Build'!$F$11:$Q$11, '1 Machine Build'!$F12:$Q12), 0), _xlfn.IFNA(_xlfn.XLOOKUP(Assumptions!F$84, '1 Machine Build'!$F$11:$Q$11, '1 Machine Build'!$F12:$Q12), 0), _xlfn.IFNA(_xlfn.XLOOKUP(Assumptions!F$85, '1 Machine Build'!$F$11:$Q$11, '1 Machine Build'!$F12:$Q12), 0), _xlfn.IFNA(_xlfn.XLOOKUP(Assumptions!F$86, '1 Machine Build'!$F$11:$Q$11, '1 Machine Build'!$F12:$Q12), 0), _xlfn.IFNA(_xlfn.XLOOKUP(Assumptions!F$87, '1 Machine Build'!$F$11:$Q$11, '1 Machine Build'!$F12:$Q12), 0), _xlfn.IFNA(_xlfn.XLOOKUP(Assumptions!F$88, '1 Machine Build'!$F$11:$Q$11, '1 Machine Build'!$F12:$Q12), 0)) -> 1391449.3 | I30: =SUM(_xlfn.IFNA(_xlfn.XLOOKUP(Assumptions!G$81, '1 Machine Build'!$F$11:$Q$11, '1 Machine Build'!$F12:$Q12), 0), _xlfn.IFNA(_xlfn.XLOOKUP(Assumptions!G$82, '1 Machine Build'!$F$11:$Q$11, '1 Machine Build'!$F12:$Q12), 0), _xlfn.IFNA(_xlfn.XLOOKUP(Assumptions!G$83, '1 Machine Build'!$F$11:$Q$11, '1 Machine Build'!$F12:$Q12), 0), _xlfn.IFNA(_xlfn.XLOOKUP(Assumptions!G$84, '1 Machine Build'!$F$11:$Q$11, '1 Machine Build'!$F12:$Q12), 0), _xlfn.IFNA(_xlfn.XLOOKUP(Assumptions!G$85, '1 Machine Build'!$F$11:$Q$11, '1 Machine Build'!$F12:$Q12), 0), _xlfn.IFNA(_xlfn.XLOOKUP(Assumptions!G$86, '1 Machine Build'!$F$11:$Q$11, '1 Machine Build'!$F12:$Q12), 0), _xlfn.IFNA(_xlfn.XLOOKUP(Assumptions!G$87, '1 Machine Build'!$F$11:$Q$11, '1 Machine Build'!$F12:$Q12), 0), _xlfn.IFNA(_xlfn.XLOOKUP(Assumptions!G$88, '1 Machine Build'!$F$11:$Q$11, '1 Machine Build'!$F12:$Q12), 0)) -> 0 | J30: =SUM(_xlfn.IFNA(_xlfn.XLOOKUP(Assumptions!H$81, '1 Machine Build'!$F$11:$Q$11, '1 Machine Build'!$F12:$Q12), 0), _xlfn.IFNA(_xlfn.XLOOKUP(Assumptions!H$82, '1 Machine Build'!$F$11:$Q$11, '1 Machine Build'!$F12:$Q12), 0), _xlfn.IFNA(_xlfn.XLOOKUP(Assumptions!H$83, '1 Machine Build'!$F$11:$Q$11, '1 Machine Build'!$F12:$Q12), 0), _xlfn.IFNA(_xlfn.XLOOKUP(Assumptions!H$84, '1 Machine Build'!$F$11:$Q$11, '1 Machine Build'!$F12:$Q12), 0), _xlfn.IFNA(_xlfn.XLOOKUP(Assumptions!H$85, '1 Machine Build'!$F$11:$Q$11, '1 Machine Build'!$F12:$Q12), 0), _xlfn.IFNA(_xlfn.XLOOKUP(Assumptions!H$86, '1 Machine Build'!$F$11:$Q$11, '1 Machine Build'!$F12:$Q12), 0), _xlfn.IFNA(_xlfn.XLOOKUP(Assumptions!H$87, '1 Machine Build'!$F$11:$Q$11, '1 Machine Build'!$F12:$Q12), 0), _xlfn.IFNA(_xlfn.XLOOKUP(Assumptions!H$88, '1 Machine Build'!$F$11:$Q$11, '1 Machine Build'!$F12:$Q12), 0)) -> 0 | K30: =SUM(_xlfn.IFNA(_xlfn.XLOOKUP(Assumptions!I$81, '1 Machine Build'!$F$11:$Q$11, '1 Machine Build'!$F12:$Q12), 0), _xlfn.IFNA(_xlfn.XLOOKUP(Assumptions!I$82, '1 Machine Build'!$F$11:$Q$11, '1 Machine Build'!$F12:$Q12), 0), _xlfn.IFNA(_xlfn.XLOOKUP(Assumptions!I$83, '1 Machine Build'!$F$11:$Q$11, '1 Machine Build'!$F12:$Q12), 0), _xlfn.IFNA(_xlfn.XLOOKUP(Assumptions!I$84, '1 Machine Build'!$F$11:$Q$11, '1 Machine Build'!$F12:$Q12), 0), _xlfn.IFNA(_xlfn.XLOOKUP(Assumptions!I$85, '1 Machine Build'!$F$11:$Q$11, '1 Machine Build'!$F12:$Q12), 0), _xlfn.IFNA(_xlfn.XLOOKUP(Assumptions!I$86, '1 Machine Build'!$F$11:$Q$11, '1 Machine Build'!$F12:$Q12), 0), _xlfn.IFNA(_xlfn.XLOOKUP(Assumptions!I$87, '1 Machine Build'!$F$11:$Q$11, '1 Machine Build'!$F12:$Q12), 0), _xlfn.IFNA(_xlfn.XLOOKUP(Assumptions!I$88, '1 Machine Build'!$F$11:$Q$11, '1 Machine Build'!$F12:$Q12), 0)) -> 0 | L30: =SUM(_xlfn.IFNA(_xlfn.XLOOKUP(Assumptions!J$81, '1 Machine Build'!$F$11:$Q$11, '1 Machine Build'!$F12:$Q12), 0), _xlfn.IFNA(_xlfn.XLOOKUP(Assumptions!J$82, '1 Machine Build'!$F$11:$Q$11, '1 Machine Build'!$F12:$Q12), 0), _xlfn.IFNA(_xlfn.XLOOKUP(Assumptions!J$83, '1 Machine Build'!$F$11:$Q$11, '1 Machine Build'!$F12:$Q12), 0), _xlfn.IFNA(_xlfn.XLOOKUP(Assumptions!J$84, '1 Machine Build'!$F$11:$Q$11, '1 Machine Build'!$F12:$Q12), 0), _xlfn.IFNA(_xlfn.XLOOKUP(Assumptions!J$85, '1 Machine Build'!$F$11:$Q$11, '1 Machine Build'!$F12:$Q12), 0), _xlfn.IFNA(_xlfn.XLOOKUP(Assumptions!J$86, '1 Machine Build'!$F$11:$Q$11, '1 Machine Build'!$F12:$Q12), 0), _xlfn.IFNA(_xlfn.XLOOKUP(Assumptions!J$87, '1 Machine Build'!$F$11:$Q$11, '1 Machine Build'!$F12:$Q12), 0), _xlfn.IFNA(_xlfn.XLOOKUP(Assumptions!J$88, '1 Machine Build'!$F$11:$Q$11, '1 Machine Build'!$F12:$Q12), 0)) -> 0 | M30: =SUM(_xlfn.IFNA(_xlfn.XLOOKUP(Assumptions!K$81, '1 Machine Build'!$F$11:$Q$11, '1 Machine Build'!$F12:$Q12), 0), _xlfn.IFNA(_xlfn.XLOOKUP(Assumptions!K$82, '1 Machine Build'!$F$11:$Q$11, '1 Machine Build'!$F12:$Q12), 0), _xlfn.IFNA(_xlfn.XLOOKUP(Assumptions!K$83, '1 Machine Build'!$F$11:$Q$11, '1 Machine Build'!$F12:$Q12), 0), _xlfn.IFNA(_xlfn.XLOOKUP(Assumptions!K$84, '1 Machine Build'!$F$11:$Q$11, '1 Machine Build'!$F12:$Q12), 0), _xlfn.IFNA(_xlfn.XLOOKUP(Assumptions!K$85, '1 Machine Build'!$F$11:$Q$11, '1 Machine Build'!$F12:$Q12), 0), _xlfn.IFNA(_xlfn.XLOOKUP(Assumptions!K$86, '1 Machine Build'!$F$11:$Q$11, '1 Machine Build'!$F12:$Q12), 0), _xlfn.IFNA(_xlfn.XLOOKUP(Assumptions!K$87, '1 Machine Build'!$F$11:$Q$11, '1 Machine Build'!$F12:$Q12), 0), _xlfn.IFNA(_xlfn.XLOOKUP(Assumptions!K$88, '1 Machine Build'!$F$11:$Q$11, '1 Machine Build'!$F12:$Q12), 0)) -> 0 | ... GC30: =SUM(_xlfn.IFNA(_xlfn.XLOOKUP(Assumptions!GA$81, '1 Machine Build'!$F$11:$Q$11, '1 Machine Build'!$F12:$Q12), 0), _xlfn.IFNA(_xlfn.XLOOKUP(Assumptions!GA$82, '1 Machine Build'!$F$11:$Q$11, '1 Machine Build'!$F12:$Q12), 0), _xlfn.IFNA(_xlfn.XLOOKUP(Assumptions!GA$83, '1 Machine Build'!$F$11:$Q$11, '1 Machine Build'!$F12:$Q12), 0), _xlfn.IFNA(_xlfn.XLOOKUP(Assumptions!GA$84, '1 Machine Build'!$F$11:$Q$11, '1 Machine Build'!$F12:$Q12), 0), _xlfn.IFNA(_xlfn.XLOOKUP(Assumptions!GA$85, '1 Machine Build'!$F$11:$Q$11, '1 Machine Build'!$F12:$Q12), 0), _xlfn.IFNA(_xlfn.XLOOKUP(Assumptions!GA$86, '1 Machine Build'!$F$11:$Q$11, '1 Machine Build'!$F12:$Q12), 0), _xlfn.IFNA(_xlfn.XLOOKUP(Assumptions!GA$87, '1 Machine Build'!$F$11:$Q$11, '1 Machine Build'!$F12:$Q12), 0), _xlfn.IFNA(_xlfn.XLOOKUP(Assumptions!GA$88, '1 Machine Build'!$F$11:$Q$11, '1 Machine Build'!$F12:$Q12), 0)) -> 0
B31: Facilities & Auxillary Support Systems | E31: =SUM(F31:GC31) -> 4697250 | F31: =SUM(_xlfn.IFNA(_xlfn.XLOOKUP(Assumptions!D$81, '1 Machine Build'!$F$11:$Q$11, '1 Machine Build'!$F13:$Q13), 0), _xlfn.IFNA(_xlfn.XLOOKUP(F$5, 'Site Construction Budget'!$E$13:$Z$13, 'Site Construction Budget'!$E$40:$Z$40), 0)) -> 1703250 | G31: =SUM(_xlfn.IFNA(_xlfn.XLOOKUP(Assumptions!E$81, '1 Machine Build'!$F$11:$Q$11, '1 Machine Build'!$F13:$Q13), 0), _xlfn.IFNA(_xlfn.XLOOKUP(G$5, 'Site Construction Budget'!$E$13:$Z$13, 'Site Construction Budget'!$E$40:$Z$40), 0)) -> 1309500 | H31: =SUM(_xlfn.IFNA(_xlfn.XLOOKUP(Assumptions!F$81, '1 Machine Build'!$F$11:$Q$11, '1 Machine Build'!$F13:$Q13), 0), _xlfn.IFNA(_xlfn.XLOOKUP(H$5, 'Site Construction Budget'!$E$13:$Z$13, 'Site Construction Budget'!$E$40:$Z$40), 0)) -> 1309500 | I31: =SUM(_xlfn.IFNA(_xlfn.XLOOKUP(Assumptions!G$81, '1 Machine Build'!$F$11:$Q$11, '1 Machine Build'!$F13:$Q13), 0), _xlfn.IFNA(_xlfn.XLOOKUP(I$5, 'Site Construction Budget'!$E$13:$Z$13, 'Site Construction Budget'!$E$40:$Z$40), 0)) -> 375000 | J31: =SUM(_xlfn.IFNA(_xlfn.XLOOKUP(Assumptions!H$81, '1 Machine Build'!$F$11:$Q$11, '1 Machine Build'!$F13:$Q13), 0), _xlfn.IFNA(_xlfn.XLOOKUP(J$5, 'Site Construction Budget'!$E$13:$Z$13, 'Site Construction Budget'!$E$40:$Z$40), 0)) -> 0 | K31: =SUM(_xlfn.IFNA(_xlfn.XLOOKUP(Assumptions!I$81, '1 Machine Build'!$F$11:$Q$11, '1 Machine Build'!$F13:$Q13), 0), _xlfn.IFNA(_xlfn.XLOOKUP(K$5, 'Site Construction Budget'!$E$13:$Z$13, 'Site Construction Budget'!$E$40:$Z$40), 0)) -> 0 | L31: =SUM(_xlfn.IFNA(_xlfn.XLOOKUP(Assumptions!J$81, '1 Machine Build'!$F$11:$Q$11, '1 Machine Build'!$F13:$Q13), 0), _xlfn.IFNA(_xlfn.XLOOKUP(L$5, 'Site Construction Budget'!$E$13:$Z$13, 'Site Construction Budget'!$E$40:$Z$40), 0)) -> 0 | M31: =SUM(_xlfn.IFNA(_xlfn.XLOOKUP(Assumptions!K$81, '1 Machine Build'!$F$11:$Q$11, '1 Machine Build'!$F13:$Q13), 0), _xlfn.IFNA(_xlfn.XLOOKUP(M$5, 'Site Construction Budget'!$E$13:$Z$13, 'Site Construction Budget'!$E$40:$Z$40), 0)) -> 0 | ... GC31: =SUM(_xlfn.IFNA(_xlfn.XLOOKUP(Assumptions!GA$81, '1 Machine Build'!$F$11:$Q$11, '1 Machine Build'!$F13:$Q13), 0), _xlfn.IFNA(_xlfn.XLOOKUP(GC$5, 'Site Construction Budget'!$E$13:$Z$13, 'Site Construction Budget'!$E$40:$Z$40), 0)) -> 0
B32: Operating Costs | E32: =SUM(F32:GC32) -> 714500 | F32: =SUM(_xlfn.IFNA(_xlfn.XLOOKUP(Assumptions!D$81, '1 Machine Build'!$F$11:$Q$11, '1 Machine Build'!$F14:$Q14), 0), _xlfn.IFNA(_xlfn.XLOOKUP(Assumptions!D$82, '1 Machine Build'!$F$11:$Q$11, '1 Machine Build'!$F14:$Q14), 0), _xlfn.IFNA(_xlfn.XLOOKUP(Assumptions!D$83, '1 Machine Build'!$F$11:$Q$11, '1 Machine Build'!$F14:$Q14), 0), _xlfn.IFNA(_xlfn.XLOOKUP(Assumptions!D$84, '1 Machine Build'!$F$11:$Q$11, '1 Machine Build'!$F14:$Q14), 0), _xlfn.IFNA(_xlfn.XLOOKUP(Assumptions!D$85, '1 Machine Build'!$F$11:$Q$11, '1 Machine Build'!$F14:$Q14), 0), _xlfn.IFNA(_xlfn.XLOOKUP(Assumptions!D$86, '1 Machine Build'!$F$11:$Q$11, '1 Machine Build'!$F14:$Q14), 0), _xlfn.IFNA(_xlfn.XLOOKUP(Assumptions!D$87, '1 Machine Build'!$F$11:$Q$11, '1 Machine Build'!$F14:$Q14), 0), _xlfn.IFNA(_xlfn.XLOOKUP(Assumptions!D$88, '1 Machine Build'!$F$11:$Q$11, '1 Machine Build'!$F14:$Q14), 0)) -> 85450 | G32: =SUM(_xlfn.IFNA(_xlfn.XLOOKUP(Assumptions!E$81, '1 Machine Build'!$F$11:$Q$11, '1 Machine Build'!$F14:$Q14), 0), _xlfn.IFNA(_xlfn.XLOOKUP(Assumptions!E$82, '1 Machine Build'!$F$11:$Q$11, '1 Machine Build'!$F14:$Q14), 0), _xlfn.IFNA(_xlfn.XLOOKUP(Assumptions!E$83, '1 Machine Build'!$F$11:$Q$11, '1 Machine Build'!$F14:$Q14), 0), _xlfn.IFNA(_xlfn.XLOOKUP(Assumptions!E$84, '1 Machine Build'!$F$11:$Q$11, '1 Machine Build'!$F14:$Q14), 0), _xlfn.IFNA(_xlfn.XLOOKUP(Assumptions!E$85, '1 Machine Build'!$F$11:$Q$11, '1 Machine Build'!$F14:$Q14), 0), _xlfn.IFNA(_xlfn.XLOOKUP(Assumptions!E$86, '1 Machine Build'!$F$11:$Q$11, '1 Machine Build'!$F14:$Q14), 0), _xlfn.IFNA(_xlfn.XLOOKUP(Assumptions!E$87, '1 Machine Build'!$F$11:$Q$11, '1 Machine Build'!$F14:$Q14), 0), _xlfn.IFNA(_xlfn.XLOOKUP(Assumptions!E$88, '1 Machine Build'!$F$11:$Q$11, '1 Machine Build'!$F14:$Q14), 0)) -> 27950 | H32: =SUM(_xlfn.IFNA(_xlfn.XLOOKUP(Assumptions!F$81, '1 Machine Build'!$F$11:$Q$11, '1 Machine Build'!$F14:$Q14), 0), _xlfn.IFNA(_xlfn.XLOOKUP(Assumptions!F$82, '1 Machine Build'!$F$11:$Q$11, '1 Machine Build'!$F14:$Q14), 0), _xlfn.IFNA(_xlfn.XLOOKUP(Assumptions!F$83, '1 Machine Build'!$F$11:$Q$11, '1 Machine Build'!$F14:$Q14), 0), _xlfn.IFNA(_xlfn.XLOOKUP(Assumptions!F$84, '1 Machine Build'!$F$11:$Q$11, '1 Machine Build'!$F14:$Q14), 0), _xlfn.IFNA(_xlfn.XLOOKUP(Assumptions!F$85, '1 Machine Build'!$F$11:$Q$11, '1 Machine Build'!$F14:$Q14), 0), _xlfn.IFNA(_xlfn.XLOOKUP(Assumptions!F$86, '1 Machine Build'!$F$11:$Q$11, '1 Machine Build'!$F14:$Q14), 0), _xlfn.IFNA(_xlfn.XLOOKUP(Assumptions!F$87, '1 Machine Build'!$F$11:$Q$11, '1 Machine Build'!$F14:$Q14), 0), _xlfn.IFNA(_xlfn.XLOOKUP(Assumptions!F$88, '1 Machine Build'!$F$11:$Q$11, '1 Machine Build'!$F14:$Q14), 0)) -> 27950 | I32: =SUM(_xlfn.IFNA(_xlfn.XLOOKUP(Assumptions!G$81, '1 Machine Build'!$F$11:$Q$11, '1 Machine Build'!$F14:$Q14), 0), _xlfn.IFNA(_xlfn.XLOOKUP(Assumptions!G$82, '1 Machine Build'!$F$11:$Q$11, '1 Machine Build'!$F14:$Q14), 0), _xlfn.IFNA(_xlfn.XLOOKUP(Assumptions!G$83, '1 Machine Build'!$F$11:$Q$11, '1 Machine Build'!$F14:$Q14), 0), _xlfn.IFNA(_xlfn.XLOOKUP(Assumptions!G$84, '1 Machine Build'!$F$11:$Q$11, '1 Machine Build'!$F14:$Q14), 0), _xlfn.IFNA(_xlfn.XLOOKUP(Assumptions!G$85, '1 Machine Build'!$F$11:$Q$11, '1 Machine Build'!$F14:$Q14), 0), _xlfn.IFNA(_xlfn.XLOOKUP(Assumptions!G$86, '1 Machine Build'!$F$11:$Q$11, '1 Machine Build'!$F14:$Q14), 0), _xlfn.IFNA(_xlfn.XLOOKUP(Assumptions!G$87, '1 Machine Build'!$F$11:$Q$11, '1 Machine Build'!$F14:$Q14), 0), _xlfn.IFNA(_xlfn.XLOOKUP(Assumptions!G$88, '1 Machine Build'!$F$11:$Q$11, '1 Machine Build'!$F14:$Q14), 0)) -> 27950 | J32: =SUM(_xlfn.IFNA(_xlfn.XLOOKUP(Assumptions!H$81, '1 Machine Build'!$F$11:$Q$11, '1 Machine Build'!$F14:$Q14), 0), _xlfn.IFNA(_xlfn.XLOOKUP(Assumptions!H$82, '1 Machine Build'!$F$11:$Q$11, '1 Machine Build'!$F14:$Q14), 0), _xlfn.IFNA(_xlfn.XLOOKUP(Assumptions!H$83, '1 Machine Build'!$F$11:$Q$11, '1 Machine Build'!$F14:$Q14), 0), _xlfn.IFNA(_xlfn.XLOOKUP(Assumptions!H$84, '1 Machine Build'!$F$11:$Q$11, '1 Machine Build'!$F14:$Q14), 0), _xlfn.IFNA(_xlfn.XLOOKUP(Assumptions!H$85, '1 Machine Build'!$F$11:$Q$11, '1 Machine Build'!$F14:$Q14), 0), _xlfn.IFNA(_xlfn.XLOOKUP(Assumptions!H$86, '1 Machine Build'!$F$11:$Q$11, '1 Machine Build'!$F14:$Q14), 0), _xlfn.IFNA(_xlfn.XLOOKUP(Assumptions!H$87, '1 Machine Build'!$F$11:$Q$11, '1 Machine Build'!$F14:$Q14), 0), _xlfn.IFNA(_xlfn.XLOOKUP(Assumptions!H$88, '1 Machine Build'!$F$11:$Q$11, '1 Machine Build'!$F14:$Q14), 0)) -> 27950 | K32: =SUM(_xlfn.IFNA(_xlfn.XLOOKUP(Assumptions!I$81, '1 Machine Build'!$F$11:$Q$11, '1 Machine Build'!$F14:$Q14), 0), _xlfn.IFNA(_xlfn.XLOOKUP(Assumptions!I$82, '1 Machine Build'!$F$11:$Q$11, '1 Machine Build'!$F14:$Q14), 0), _xlfn.IFNA(_xlfn.XLOOKUP(Assumptions!I$83, '1 Machine Build'!$F$11:$Q$11, '1 Machine Build'!$F14:$Q14), 0), _xlfn.IFNA(_xlfn.XLOOKUP(Assumptions!I$84, '1 Machine Build'!$F$11:$Q$11, '1 Machine Build'!$F14:$Q14), 0), _xlfn.IFNA(_xlfn.XLOOKUP(Assumptions!I$85, '1 Machine Build'!$F$11:$Q$11, '1 Machine Build'!$F14:$Q14), 0), _xlfn.IFNA(_xlfn.XLOOKUP(Assumptions!I$86, '1 Machine Build'!$F$11:$Q$11, '1 Machine Build'!$F14:$Q14), 0), _xlfn.IFNA(_xlfn.XLOOKUP(Assumptions!I$87, '1 Machine Build'!$F$11:$Q$11, '1 Machine Build'!$F14:$Q14), 0), _xlfn.IFNA(_xlfn.XLOOKUP(Assumptions!I$88, '1 Machine Build'!$F$11:$Q$11, '1 Machine Build'!$F14:$Q14), 0)) -> 204016.67 | L32: =SUM(_xlfn.IFNA(_xlfn.XLOOKUP(Assumptions!J$81, '1 Machine Build'!$F$11:$Q$11, '1 Machine Build'!$F14:$Q14), 0), _xlfn.IFNA(_xlfn.XLOOKUP(Assumptions!J$82, '1 Machine Build'!$F$11:$Q$11, '1 Machine Build'!$F14:$Q14), 0), _xlfn.IFNA(_xlfn.XLOOKUP(Assumptions!J$83, '1 Machine Build'!$F$11:$Q$11, '1 Machine Build'!$F14:$Q14), 0), _xlfn.IFNA(_xlfn.XLOOKUP(Assumptions!J$84, '1 Machine Build'!$F$11:$Q$11, '1 Machine Build'!$F14:$Q14), 0), _xlfn.IFNA(_xlfn.XLOOKUP(Assumptions!J$85, '1 Machine Build'!$F$11:$Q$11, '1 Machine Build'!$F14:$Q14), 0), _xlfn.IFNA(_xlfn.XLOOKUP(Assumptions!J$86, '1 Machine Build'!$F$11:$Q$11, '1 Machine Build'!$F14:$Q14), 0), _xlfn.IFNA(_xlfn.XLOOKUP(Assumptions!J$87, '1 Machine Build'!$F$11:$Q$11, '1 Machine Build'!$F14:$Q14), 0), _xlfn.IFNA(_xlfn.XLOOKUP(Assumptions!J$88, '1 Machine Build'!$F$11:$Q$11, '1 Machine Build'!$F14:$Q14), 0)) -> 144616.67 | M32: =SUM(_xlfn.IFNA(_xlfn.XLOOKUP(Assumptions!K$81, '1 Machine Build'!$F$11:$Q$11, '1 Machine Build'!$F14:$Q14), 0), _xlfn.IFNA(_xlfn.XLOOKUP(Assumptions!K$82, '1 Machine Build'!$F$11:$Q$11, '1 Machine Build'!$F14:$Q14), 0), _xlfn.IFNA(_xlfn.XLOOKUP(Assumptions!K$83, '1 Machine Build'!$F$11:$Q$11, '1 Machine Build'!$F14:$Q14), 0), _xlfn.IFNA(_xlfn.XLOOKUP(Assumptions!K$84, '1 Machine Build'!$F$11:$Q$11, '1 Machine Build'!$F14:$Q14), 0), _xlfn.IFNA(_xlfn.XLOOKUP(Assumptions!K$85, '1 Machine Build'!$F$11:$Q$11, '1 Machine Build'!$F14:$Q14), 0), _xlfn.IFNA(_xlfn.XLOOKUP(Assumptions!K$86, '1 Machine Build'!$F$11:$Q$11, '1 Machine Build'!$F14:$Q14), 0), _xlfn.IFNA(_xlfn.XLOOKUP(Assumptions!K$87, '1 Machine Build'!$F$11:$Q$11, '1 Machine Build'!$F14:$Q14), 0), _xlfn.IFNA(_xlfn.XLOOKUP(Assumptions!K$88, '1 Machine Build'!$F$11:$Q$11, '1 Machine Build'!$F14:$Q14), 0)) -> 144616.67 | ... GC32: =SUM(_xlfn.IFNA(_xlfn.XLOOKUP(Assumptions!GA$81, '1 Machine Build'!$F$11:$Q$11, '1 Machine Build'!$F14:$Q14), 0), _xlfn.IFNA(_xlfn.XLOOKUP(Assumptions!GA$82, '1 Machine Build'!$F$11:$Q$11, '1 Machine Build'!$F14:$Q14), 0), _xlfn.IFNA(_xlfn.XLOOKUP(Assumptions!GA$83, '1 Machine Build'!$F$11:$Q$11, '1 Machine Build'!$F14:$Q14), 0), _xlfn.IFNA(_xlfn.XLOOKUP(Assumptions!GA$84, '1 Machine Build'!$F$11:$Q$11, '1 Machine Build'!$F14:$Q14), 0), _xlfn.IFNA(_xlfn.XLOOKUP(Assumptions!GA$85, '1 Machine Build'!$F$11:$Q$11, '1 Machine Build'!$F14:$Q14), 0), _xlfn.IFNA(_xlfn.XLOOKUP(Assumptions!GA$86, '1 Machine Build'!$F$11:$Q$11, '1 Machine Build'!$F14:$Q14), 0), _xlfn.IFNA(_xlfn.XLOOKUP(Assumptions!GA$87, '1 Machine Build'!$F$11:$Q$11, '1 Machine Build'!$F14:$Q14), 0), _xlfn.IFNA(_xlfn.XLOOKUP(Assumptions!GA$88, '1 Machine Build'!$F$11:$Q$11, '1 Machine Build'!$F14:$Q14), 0)) -> 0
B33: Professional Services | E33: =SUM(F33:GC33) -> 401400 | F33: =SUM(_xlfn.IFNA(_xlfn.XLOOKUP(Assumptions!D$81, '1 Machine Build'!$F$11:$Q$11, '1 Machine Build'!$F15:$Q15), 0), _xlfn.IFNA(_xlfn.XLOOKUP(Assumptions!D$82, '1 Machine Build'!$F$11:$Q$11, '1 Machine Build'!$F15:$Q15), 0), _xlfn.IFNA(_xlfn.XLOOKUP(Assumptions!D$83, '1 Machine Build'!$F$11:$Q$11, '1 Machine Build'!$F15:$Q15), 0), _xlfn.IFNA(_xlfn.XLOOKUP(Assumptions!D$84, '1 Machine Build'!$F$11:$Q$11, '1 Machine Build'!$F15:$Q15), 0), _xlfn.IFNA(_xlfn.XLOOKUP(Assumptions!D$85, '1 Machine Build'!$F$11:$Q$11, '1 Machine Build'!$F15:$Q15), 0), _xlfn.IFNA(_xlfn.XLOOKUP(Assumptions!D$86, '1 Machine Build'!$F$11:$Q$11, '1 Machine Build'!$F15:$Q15), 0), _xlfn.IFNA(_xlfn.XLOOKUP(Assumptions!D$87, '1 Machine Build'!$F$11:$Q$11, '1 Machine Build'!$F15:$Q15), 0), _xlfn.IFNA(_xlfn.XLOOKUP(Assumptions!D$88, '1 Machine Build'!$F$11:$Q$11, '1 Machine Build'!$F15:$Q15), 0)) -> 364550 | G33: =SUM(_xlfn.IFNA(_xlfn.XLOOKUP(Assumptions!E$81, '1 Machine Build'!$F$11:$Q$11, '1 Machine Build'!$F15:$Q15), 0), _xlfn.IFNA(_xlfn.XLOOKUP(Assumptions!E$82, '1 Machine Build'!$F$11:$Q$11, '1 Machine Build'!$F15:$Q15), 0), _xlfn.IFNA(_xlfn.XLOOKUP(Assumptions!E$83, '1 Machine Build'!$F$11:$Q$11, '1 Machine Build'!$F15:$Q15), 0), _xlfn.IFNA(_xlfn.XLOOKUP(Assumptions!E$84, '1 Machine Build'!$F$11:$Q$11, '1 Machine Build'!$F15:$Q15), 0), _xlfn.IFNA(_xlfn.XLOOKUP(Assumptions!E$85, '1 Machine Build'!$F$11:$Q$11, '1 Machine Build'!$F15:$Q15), 0), _xlfn.IFNA(_xlfn.XLOOKUP(Assumptions!E$86, '1 Machine Build'!$F$11:$Q$11, '1 Machine Build'!$F15:$Q15), 0), _xlfn.IFNA(_xlfn.XLOOKUP(Assumptions!E$87, '1 Machine Build'!$F$11:$Q$11, '1 Machine Build'!$F15:$Q15), 0), _xlfn.IFNA(_xlfn.XLOOKUP(Assumptions!E$88, '1 Machine Build'!$F$11:$Q$11, '1 Machine Build'!$F15:$Q15), 0)) -> 4550 | H33: =SUM(_xlfn.IFNA(_xlfn.XLOOKUP(Assumptions!F$81, '1 Machine Build'!$F$11:$Q$11, '1 Machine Build'!$F15:$Q15), 0), _xlfn.IFNA(_xlfn.XLOOKUP(Assumptions!F$82, '1 Machine Build'!$F$11:$Q$11, '1 Machine Build'!$F15:$Q15), 0), _xlfn.IFNA(_xlfn.XLOOKUP(Assumptions!F$83, '1 Machine Build'!$F$11:$Q$11, '1 Machine Build'!$F15:$Q15), 0), _xlfn.IFNA(_xlfn.XLOOKUP(Assumptions!F$84, '1 Machine Build'!$F$11:$Q$11, '1 Machine Build'!$F15:$Q15), 0), _xlfn.IFNA(_xlfn.XLOOKUP(Assumptions!F$85, '1 Machine Build'!$F$11:$Q$11, '1 Machine Build'!$F15:$Q15), 0), _xlfn.IFNA(_xlfn.XLOOKUP(Assumptions!F$86, '1 Machine Build'!$F$11:$Q$11, '1 Machine Build'!$F15:$Q15), 0), _xlfn.IFNA(_xlfn.XLOOKUP(Assumptions!F$87, '1 Machine Build'!$F$11:$Q$11, '1 Machine Build'!$F15:$Q15), 0), _xlfn.IFNA(_xlfn.XLOOKUP(Assumptions!F$88, '1 Machine Build'!$F$11:$Q$11, '1 Machine Build'!$F15:$Q15), 0)) -> 4550 | I33: =SUM(_xlfn.IFNA(_xlfn.XLOOKUP(Assumptions!G$81, '1 Machine Build'!$F$11:$Q$11, '1 Machine Build'!$F15:$Q15), 0), _xlfn.IFNA(_xlfn.XLOOKUP(Assumptions!G$82, '1 Machine Build'!$F$11:$Q$11, '1 Machine Build'!$F15:$Q15), 0), _xlfn.IFNA(_xlfn.XLOOKUP(Assumptions!G$83, '1 Machine Build'!$F$11:$Q$11, '1 Machine Build'!$F15:$Q15), 0), _xlfn.IFNA(_xlfn.XLOOKUP(Assumptions!G$84, '1 Machine Build'!$F$11:$Q$11, '1 Machine Build'!$F15:$Q15), 0), _xlfn.IFNA(_xlfn.XLOOKUP(Assumptions!G$85, '1 Machine Build'!$F$11:$Q$11, '1 Machine Build'!$F15:$Q15), 0), _xlfn.IFNA(_xlfn.XLOOKUP(Assumptions!G$86, '1 Machine Build'!$F$11:$Q$11, '1 Machine Build'!$F15:$Q15), 0), _xlfn.IFNA(_xlfn.XLOOKUP(Assumptions!G$87, '1 Machine Build'!$F$11:$Q$11, '1 Machine Build'!$F15:$Q15), 0), _xlfn.IFNA(_xlfn.XLOOKUP(Assumptions!G$88, '1 Machine Build'!$F$11:$Q$11, '1 Machine Build'!$F15:$Q15), 0)) -> 4550 | J33: =SUM(_xlfn.IFNA(_xlfn.XLOOKUP(Assumptions!H$81, '1 Machine Build'!$F$11:$Q$11, '1 Machine Build'!$F15:$Q15), 0), _xlfn.IFNA(_xlfn.XLOOKUP(Assumptions!H$82, '1 Machine Build'!$F$11:$Q$11, '1 Machine Build'!$F15:$Q15), 0), _xlfn.IFNA(_xlfn.XLOOKUP(Assumptions!H$83, '1 Machine Build'!$F$11:$Q$11, '1 Machine Build'!$F15:$Q15), 0), _xlfn.IFNA(_xlfn.XLOOKUP(Assumptions!H$84, '1 Machine Build'!$F$11:$Q$11, '1 Machine Build'!$F15:$Q15), 0), _xlfn.IFNA(_xlfn.XLOOKUP(Assumptions!H$85, '1 Machine Build'!$F$11:$Q$11, '1 Machine Build'!$F15:$Q15), 0), _xlfn.IFNA(_xlfn.XLOOKUP(Assumptions!H$86, '1 Machine Build'!$F$11:$Q$11, '1 Machine Build'!$F15:$Q15), 0), _xlfn.IFNA(_xlfn.XLOOKUP(Assumptions!H$87, '1 Machine Build'!$F$11:$Q$11, '1 Machine Build'!$F15:$Q15), 0), _xlfn.IFNA(_xlfn.XLOOKUP(Assumptions!H$88, '1 Machine Build'!$F$11:$Q$11, '1 Machine Build'!$F15:$Q15), 0)) -> 9550 | K33: =SUM(_xlfn.IFNA(_xlfn.XLOOKUP(Assumptions!I$81, '1 Machine Build'!$F$11:$Q$11, '1 Machine Build'!$F15:$Q15), 0), _xlfn.IFNA(_xlfn.XLOOKUP(Assumptions!I$82, '1 Machine Build'!$F$11:$Q$11, '1 Machine Build'!$F15:$Q15), 0), _xlfn.IFNA(_xlfn.XLOOKUP(Assumptions!I$83, '1 Machine Build'!$F$11:$Q$11, '1 Machine Build'!$F15:$Q15), 0), _xlfn.IFNA(_xlfn.XLOOKUP(Assumptions!I$84, '1 Machine Build'!$F$11:$Q$11, '1 Machine Build'!$F15:$Q15), 0), _xlfn.IFNA(_xlfn.XLOOKUP(Assumptions!I$85, '1 Machine Build'!$F$11:$Q$11, '1 Machine Build'!$F15:$Q15), 0), _xlfn.IFNA(_xlfn.XLOOKUP(Assumptions!I$86, '1 Machine Build'!$F$11:$Q$11, '1 Machine Build'!$F15:$Q15), 0), _xlfn.IFNA(_xlfn.XLOOKUP(Assumptions!I$87, '1 Machine Build'!$F$11:$Q$11, '1 Machine Build'!$F15:$Q15), 0), _xlfn.IFNA(_xlfn.XLOOKUP(Assumptions!I$88, '1 Machine Build'!$F$11:$Q$11, '1 Machine Build'!$F15:$Q15), 0)) -> 4550 | L33: =SUM(_xlfn.IFNA(_xlfn.XLOOKUP(Assumptions!J$81, '1 Machine Build'!$F$11:$Q$11, '1 Machine Build'!$F15:$Q15), 0), _xlfn.IFNA(_xlfn.XLOOKUP(Assumptions!J$82, '1 Machine Build'!$F$11:$Q$11, '1 Machine Build'!$F15:$Q15), 0), _xlfn.IFNA(_xlfn.XLOOKUP(Assumptions!J$83, '1 Machine Build'!$F$11:$Q$11, '1 Machine Build'!$F15:$Q15), 0), _xlfn.IFNA(_xlfn.XLOOKUP(Assumptions!J$84, '1 Machine Build'!$F$11:$Q$11, '1 Machine Build'!$F15:$Q15), 0), _xlfn.IFNA(_xlfn.XLOOKUP(Assumptions!J$85, '1 Machine Build'!$F$11:$Q$11, '1 Machine Build'!$F15:$Q15), 0), _xlfn.IFNA(_xlfn.XLOOKUP(Assumptions!J$86, '1 Machine Build'!$F$11:$Q$11, '1 Machine Build'!$F15:$Q15), 0), _xlfn.IFNA(_xlfn.XLOOKUP(Assumptions!J$87, '1 Machine Build'!$F$11:$Q$11, '1 Machine Build'!$F15:$Q15), 0), _xlfn.IFNA(_xlfn.XLOOKUP(Assumptions!J$88, '1 Machine Build'!$F$11:$Q$11, '1 Machine Build'!$F15:$Q15), 0)) -> 4550 | M33: =SUM(_xlfn.IFNA(_xlfn.XLOOKUP(Assumptions!K$81, '1 Machine Build'!$F$11:$Q$11, '1 Machine Build'!$F15:$Q15), 0), _xlfn.IFNA(_xlfn.XLOOKUP(Assumptions!K$82, '1 Machine Build'!$F$11:$Q$11, '1 Machine Build'!$F15:$Q15), 0), _xlfn.IFNA(_xlfn.XLOOKUP(Assumptions!K$83, '1 Machine Build'!$F$11:$Q$11, '1 Machine Build'!$F15:$Q15), 0), _xlfn.IFNA(_xlfn.XLOOKUP(Assumptions!K$84, '1 Machine Build'!$F$11:$Q$11, '1 Machine Build'!$F15:$Q15), 0), _xlfn.IFNA(_xlfn.XLOOKUP(Assumptions!K$85, '1 Machine Build'!$F$11:$Q$11, '1 Machine Build'!$F15:$Q15), 0), _xlfn.IFNA(_xlfn.XLOOKUP(Assumptions!K$86, '1 Machine Build'!$F$11:$Q$11, '1 Machine Build'!$F15:$Q15), 0), _xlfn.IFNA(_xlfn.XLOOKUP(Assumptions!K$87, '1 Machine Build'!$F$11:$Q$11, '1 Machine Build'!$F15:$Q15), 0), _xlfn.IFNA(_xlfn.XLOOKUP(Assumptions!K$88, '1 Machine Build'!$F$11:$Q$11, '1 Machine Build'!$F15:$Q15), 0)) -> 4550 | ... GC33: =SUM(_xlfn.IFNA(_xlfn.XLOOKUP(Assumptions!GA$81, '1 Machine Build'!$F$11:$Q$11, '1 Machine Build'!$F15:$Q15), 0), _xlfn.IFNA(_xlfn.XLOOKUP(Assumptions!GA$82, '1 Machine Build'!$F$11:$Q$11, '1 Machine Build'!$F15:$Q15), 0), _xlfn.IFNA(_xlfn.XLOOKUP(Assumptions!GA$83, '1 Machine Build'!$F$11:$Q$11, '1 Machine Build'!$F15:$Q15), 0), _xlfn.IFNA(_xlfn.XLOOKUP(Assumptions!GA$84, '1 Machine Build'!$F$11:$Q$11, '1 Machine Build'!$F15:$Q15), 0), _xlfn.IFNA(_xlfn.XLOOKUP(Assumptions!GA$85, '1 Machine Build'!$F$11:$Q$11, '1 Machine Build'!$F15:$Q15), 0), _xlfn.IFNA(_xlfn.XLOOKUP(Assumptions!GA$86, '1 Machine Build'!$F$11:$Q$11, '1 Machine Build'!$F15:$Q15), 0), _xlfn.IFNA(_xlfn.XLOOKUP(Assumptions!GA$87, '1 Machine Build'!$F$11:$Q$11, '1 Machine Build'!$F15:$Q15), 0), _xlfn.IFNA(_xlfn.XLOOKUP(Assumptions!GA$88, '1 Machine Build'!$F$11:$Q$11, '1 Machine Build'!$F15:$Q15), 0)) -> 0
